{
  "version": 8,
  "blockIdVersion": 11,
  "anchorX": 0,
  "anchorY": 0,
  "anchorZ": 0,
  "blocks": [
    {
      "x": -7,
      "y": 0,
      "z": -7,
      "name": "Rock_Stone"
    },
    {
      "x": -7,
      "y": 1,
      "z": -7,
      "name": "Rock_Stone"
    },
    {
      "x": -7,
      "y": 2,
      "z": -7,
      "name": "Rock_Stone"
    },
    {
      "x": -7,
      "y": 3,
      "z": -7,
      "name": "Rock_Stone"
    },
    {
      "x": -7,
      "y": 4,
      "z": -7,
      "name": "Rock_Stone"
    },
    {
      "x": -7,
      "y": 5,
      "z": -7,
      "name": "Rock_Stone"
    },
    {
      "x": -7,
      "y": 6,
      "z": -7,
      "name": "Rock_Stone"
    },
    {
      "x": -7,
      "y": 7,
      "z": -7,
      "name": "Rock_Stone"
    },
    {
      "x": -7,
      "y": 8,
      "z": -7,
      "name": "Rock_Stone"
    },
    {
      "x": -7,
      "y": 9,
      "z": -7,
      "name": "Rock_Stone"
    },
    {
      "x": -7,
      "y": 10,
      "z": -7,
      "name": "Rock_Stone"
    },
    {
      "x": -7,
      "y": 11,
      "z": -7,
      "name": "Rock_Stone"
    },
    {
      "x": -7,
      "y": 12,
      "z": -7,
      "name": "Rock_Stone"
    },
    {
      "x": -7,
      "y": 13,
      "z": -7,
      "name": "Soil_Dirt"
    },
    {
      "x": -7,
      "y": 14,
      "z": -7,
      "name": "Soil_Dirt"
    },
    {
      "x": -7,
      "y": 15,
      "z": -7,
      "name": "Soil_Dirt"
    },
    {
      "x": -7,
      "y": 16,
      "z": -7,
      "name": "Soil_Grass"
    },
    {
      "x": -7,
      "y": 0,
      "z": -6,
      "name": "Rock_Stone"
    },
    {
      "x": -7,
      "y": 1,
      "z": -6,
      "name": "Rock_Stone"
    },
    {
      "x": -7,
      "y": 2,
      "z": -6,
      "name": "Rock_Stone"
    },
    {
      "x": -7,
      "y": 3,
      "z": -6,
      "name": "Rock_Stone"
    },
    {
      "x": -7,
      "y": 4,
      "z": -6,
      "name": "Rock_Stone"
    },
    {
      "x": -7,
      "y": 5,
      "z": -6,
      "name": "Rock_Stone"
    },
    {
      "x": -7,
      "y": 6,
      "z": -6,
      "name": "Rock_Stone"
    },
    {
      "x": -7,
      "y": 7,
      "z": -6,
      "name": "Rock_Stone"
    },
    {
      "x": -7,
      "y": 8,
      "z": -6,
      "name": "Rock_Stone"
    },
    {
      "x": -7,
      "y": 9,
      "z": -6,
      "name": "Rock_Stone"
    },
    {
      "x": -7,
      "y": 10,
      "z": -6,
      "name": "Rock_Stone"
    },
    {
      "x": -7,
      "y": 11,
      "z": -6,
      "name": "Rock_Stone"
    },
    {
      "x": -7,
      "y": 12,
      "z": -6,
      "name": "Rock_Stone"
    },
    {
      "x": -7,
      "y": 13,
      "z": -6,
      "name": "Soil_Dirt"
    },
    {
      "x": -7,
      "y": 14,
      "z": -6,
      "name": "Soil_Dirt"
    },
    {
      "x": -7,
      "y": 15,
      "z": -6,
      "name": "Soil_Dirt"
    },
    {
      "x": -7,
      "y": 16,
      "z": -6,
      "name": "Soil_Grass"
    },
    {
      "x": -7,
      "y": 0,
      "z": -5,
      "name": "Rock_Stone"
    },
    {
      "x": -7,
      "y": 1,
      "z": -5,
      "name": "Rock_Stone"
    },
    {
      "x": -7,
      "y": 2,
      "z": -5,
      "name": "Rock_Stone"
    },
    {
      "x": -7,
      "y": 3,
      "z": -5,
      "name": "Rock_Stone"
    },
    {
      "x": -7,
      "y": 4,
      "z": -5,
      "name": "Rock_Stone"
    },
    {
      "x": -7,
      "y": 5,
      "z": -5,
      "name": "Rock_Stone"
    },
    {
      "x": -7,
      "y": 6,
      "z": -5,
      "name": "Rock_Stone"
    },
    {
      "x": -7,
      "y": 7,
      "z": -5,
      "name": "Rock_Stone"
    },
    {
      "x": -7,
      "y": 8,
      "z": -5,
      "name": "Rock_Stone"
    },
    {
      "x": -7,
      "y": 9,
      "z": -5,
      "name": "Rock_Stone"
    },
    {
      "x": -7,
      "y": 10,
      "z": -5,
      "name": "Rock_Stone"
    },
    {
      "x": -7,
      "y": 11,
      "z": -5,
      "name": "Rock_Stone"
    },
    {
      "x": -7,
      "y": 12,
      "z": -5,
      "name": "Rock_Stone"
    },
    {
      "x": -7,
      "y": 13,
      "z": -5,
      "name": "Soil_Dirt"
    },
    {
      "x": -7,
      "y": 14,
      "z": -5,
      "name": "Soil_Dirt"
    },
    {
      "x": -7,
      "y": 15,
      "z": -5,
      "name": "Soil_Dirt"
    },
    {
      "x": -7,
      "y": 16,
      "z": -5,
      "name": "Soil_Grass"
    },
    {
      "x": -7,
      "y": 0,
      "z": -4,
      "name": "Rock_Stone"
    },
    {
      "x": -7,
      "y": 1,
      "z": -4,
      "name": "Rock_Stone"
    },
    {
      "x": -7,
      "y": 2,
      "z": -4,
      "name": "Rock_Stone"
    },
    {
      "x": -7,
      "y": 3,
      "z": -4,
      "name": "Rock_Stone"
    },
    {
      "x": -7,
      "y": 4,
      "z": -4,
      "name": "Rock_Stone"
    },
    {
      "x": -7,
      "y": 5,
      "z": -4,
      "name": "Rock_Stone"
    },
    {
      "x": -7,
      "y": 6,
      "z": -4,
      "name": "Rock_Stone"
    },
    {
      "x": -7,
      "y": 7,
      "z": -4,
      "name": "Rock_Stone"
    },
    {
      "x": -7,
      "y": 8,
      "z": -4,
      "name": "Rock_Stone"
    },
    {
      "x": -7,
      "y": 9,
      "z": -4,
      "name": "Rock_Stone"
    },
    {
      "x": -7,
      "y": 10,
      "z": -4,
      "name": "Rock_Stone"
    },
    {
      "x": -7,
      "y": 11,
      "z": -4,
      "name": "Rock_Stone"
    },
    {
      "x": -7,
      "y": 12,
      "z": -4,
      "name": "Rock_Stone"
    },
    {
      "x": -7,
      "y": 13,
      "z": -4,
      "name": "Soil_Dirt"
    },
    {
      "x": -7,
      "y": 14,
      "z": -4,
      "name": "Soil_Dirt"
    },
    {
      "x": -7,
      "y": 15,
      "z": -4,
      "name": "Soil_Dirt"
    },
    {
      "x": -7,
      "y": 16,
      "z": -4,
      "name": "Soil_Grass"
    },
    {
      "x": -7,
      "y": 0,
      "z": -3,
      "name": "Rock_Stone"
    },
    {
      "x": -7,
      "y": 1,
      "z": -3,
      "name": "Rock_Stone"
    },
    {
      "x": -7,
      "y": 2,
      "z": -3,
      "name": "Rock_Stone"
    },
    {
      "x": -7,
      "y": 3,
      "z": -3,
      "name": "Rock_Stone"
    },
    {
      "x": -7,
      "y": 4,
      "z": -3,
      "name": "Rock_Stone"
    },
    {
      "x": -7,
      "y": 5,
      "z": -3,
      "name": "Rock_Stone"
    },
    {
      "x": -7,
      "y": 6,
      "z": -3,
      "name": "Rock_Stone"
    },
    {
      "x": -7,
      "y": 7,
      "z": -3,
      "name": "Rock_Stone"
    },
    {
      "x": -7,
      "y": 8,
      "z": -3,
      "name": "Rock_Stone"
    },
    {
      "x": -7,
      "y": 9,
      "z": -3,
      "name": "Rock_Stone"
    },
    {
      "x": -7,
      "y": 10,
      "z": -3,
      "name": "Rock_Stone"
    },
    {
      "x": -7,
      "y": 11,
      "z": -3,
      "name": "Rock_Stone"
    },
    {
      "x": -7,
      "y": 12,
      "z": -3,
      "name": "Rock_Stone"
    },
    {
      "x": -7,
      "y": 13,
      "z": -3,
      "name": "Soil_Dirt"
    },
    {
      "x": -7,
      "y": 14,
      "z": -3,
      "name": "Soil_Dirt"
    },
    {
      "x": -7,
      "y": 15,
      "z": -3,
      "name": "Soil_Dirt"
    },
    {
      "x": -7,
      "y": 16,
      "z": -3,
      "name": "Soil_Grass"
    },
    {
      "x": -7,
      "y": 0,
      "z": -2,
      "name": "Rock_Stone"
    },
    {
      "x": -7,
      "y": 1,
      "z": -2,
      "name": "Rock_Stone"
    },
    {
      "x": -7,
      "y": 2,
      "z": -2,
      "name": "Rock_Stone"
    },
    {
      "x": -7,
      "y": 3,
      "z": -2,
      "name": "Rock_Stone"
    },
    {
      "x": -7,
      "y": 4,
      "z": -2,
      "name": "Rock_Stone"
    },
    {
      "x": -7,
      "y": 5,
      "z": -2,
      "name": "Rock_Stone"
    },
    {
      "x": -7,
      "y": 6,
      "z": -2,
      "name": "Rock_Stone"
    },
    {
      "x": -7,
      "y": 7,
      "z": -2,
      "name": "Rock_Stone"
    },
    {
      "x": -7,
      "y": 8,
      "z": -2,
      "name": "Rock_Stone"
    },
    {
      "x": -7,
      "y": 9,
      "z": -2,
      "name": "Rock_Stone"
    },
    {
      "x": -7,
      "y": 10,
      "z": -2,
      "name": "Rock_Stone"
    },
    {
      "x": -7,
      "y": 11,
      "z": -2,
      "name": "Rock_Stone"
    },
    {
      "x": -7,
      "y": 12,
      "z": -2,
      "name": "Rock_Stone"
    },
    {
      "x": -7,
      "y": 13,
      "z": -2,
      "name": "Soil_Dirt"
    },
    {
      "x": -7,
      "y": 14,
      "z": -2,
      "name": "Soil_Dirt"
    },
    {
      "x": -7,
      "y": 15,
      "z": -2,
      "name": "Soil_Dirt"
    },
    {
      "x": -7,
      "y": 16,
      "z": -2,
      "name": "Soil_Grass"
    },
    {
      "x": -7,
      "y": 0,
      "z": -1,
      "name": "Rock_Stone"
    },
    {
      "x": -7,
      "y": 1,
      "z": -1,
      "name": "Rock_Stone"
    },
    {
      "x": -7,
      "y": 2,
      "z": -1,
      "name": "Rock_Stone"
    },
    {
      "x": -7,
      "y": 3,
      "z": -1,
      "name": "Rock_Stone"
    },
    {
      "x": -7,
      "y": 4,
      "z": -1,
      "name": "Rock_Stone"
    },
    {
      "x": -7,
      "y": 5,
      "z": -1,
      "name": "Rock_Stone"
    },
    {
      "x": -7,
      "y": 6,
      "z": -1,
      "name": "Rock_Stone"
    },
    {
      "x": -7,
      "y": 7,
      "z": -1,
      "name": "Rock_Stone"
    },
    {
      "x": -7,
      "y": 8,
      "z": -1,
      "name": "Rock_Stone"
    },
    {
      "x": -7,
      "y": 9,
      "z": -1,
      "name": "Rock_Stone"
    },
    {
      "x": -7,
      "y": 10,
      "z": -1,
      "name": "Rock_Stone"
    },
    {
      "x": -7,
      "y": 11,
      "z": -1,
      "name": "Rock_Stone"
    },
    {
      "x": -7,
      "y": 12,
      "z": -1,
      "name": "Rock_Stone"
    },
    {
      "x": -7,
      "y": 13,
      "z": -1,
      "name": "Soil_Dirt"
    },
    {
      "x": -7,
      "y": 14,
      "z": -1,
      "name": "Soil_Dirt"
    },
    {
      "x": -7,
      "y": 15,
      "z": -1,
      "name": "Soil_Dirt"
    },
    {
      "x": -7,
      "y": 16,
      "z": -1,
      "name": "Soil_Grass"
    },
    {
      "x": -7,
      "y": 0,
      "z": 0,
      "name": "Rock_Stone"
    },
    {
      "x": -7,
      "y": 1,
      "z": 0,
      "name": "Rock_Stone"
    },
    {
      "x": -7,
      "y": 2,
      "z": 0,
      "name": "Rock_Stone"
    },
    {
      "x": -7,
      "y": 3,
      "z": 0,
      "name": "Rock_Stone"
    },
    {
      "x": -7,
      "y": 4,
      "z": 0,
      "name": "Rock_Stone"
    },
    {
      "x": -7,
      "y": 5,
      "z": 0,
      "name": "Rock_Stone"
    },
    {
      "x": -7,
      "y": 6,
      "z": 0,
      "name": "Rock_Stone"
    },
    {
      "x": -7,
      "y": 7,
      "z": 0,
      "name": "Rock_Stone"
    },
    {
      "x": -7,
      "y": 8,
      "z": 0,
      "name": "Rock_Stone"
    },
    {
      "x": -7,
      "y": 9,
      "z": 0,
      "name": "Rock_Stone"
    },
    {
      "x": -7,
      "y": 10,
      "z": 0,
      "name": "Rock_Stone"
    },
    {
      "x": -7,
      "y": 11,
      "z": 0,
      "name": "Rock_Stone"
    },
    {
      "x": -7,
      "y": 12,
      "z": 0,
      "name": "Rock_Stone"
    },
    {
      "x": -7,
      "y": 13,
      "z": 0,
      "name": "Soil_Dirt"
    },
    {
      "x": -7,
      "y": 14,
      "z": 0,
      "name": "Soil_Dirt"
    },
    {
      "x": -7,
      "y": 15,
      "z": 0,
      "name": "Soil_Dirt"
    },
    {
      "x": -7,
      "y": 16,
      "z": 0,
      "name": "Soil_Grass"
    },
    {
      "x": -7,
      "y": 0,
      "z": 1,
      "name": "Rock_Stone"
    },
    {
      "x": -7,
      "y": 1,
      "z": 1,
      "name": "Rock_Stone"
    },
    {
      "x": -7,
      "y": 2,
      "z": 1,
      "name": "Rock_Stone"
    },
    {
      "x": -7,
      "y": 3,
      "z": 1,
      "name": "Rock_Stone"
    },
    {
      "x": -7,
      "y": 4,
      "z": 1,
      "name": "Rock_Stone"
    },
    {
      "x": -7,
      "y": 5,
      "z": 1,
      "name": "Rock_Stone"
    },
    {
      "x": -7,
      "y": 6,
      "z": 1,
      "name": "Rock_Stone"
    },
    {
      "x": -7,
      "y": 7,
      "z": 1,
      "name": "Rock_Stone"
    },
    {
      "x": -7,
      "y": 8,
      "z": 1,
      "name": "Rock_Stone"
    },
    {
      "x": -7,
      "y": 9,
      "z": 1,
      "name": "Rock_Stone"
    },
    {
      "x": -7,
      "y": 10,
      "z": 1,
      "name": "Rock_Stone"
    },
    {
      "x": -7,
      "y": 11,
      "z": 1,
      "name": "Rock_Stone"
    },
    {
      "x": -7,
      "y": 12,
      "z": 1,
      "name": "Rock_Stone"
    },
    {
      "x": -7,
      "y": 13,
      "z": 1,
      "name": "Soil_Dirt"
    },
    {
      "x": -7,
      "y": 14,
      "z": 1,
      "name": "Soil_Dirt"
    },
    {
      "x": -7,
      "y": 15,
      "z": 1,
      "name": "Soil_Dirt"
    },
    {
      "x": -7,
      "y": 16,
      "z": 1,
      "name": "Soil_Grass"
    },
    {
      "x": -7,
      "y": 0,
      "z": 2,
      "name": "Rock_Stone"
    },
    {
      "x": -7,
      "y": 1,
      "z": 2,
      "name": "Rock_Stone"
    },
    {
      "x": -7,
      "y": 2,
      "z": 2,
      "name": "Rock_Stone"
    },
    {
      "x": -7,
      "y": 3,
      "z": 2,
      "name": "Rock_Stone"
    },
    {
      "x": -7,
      "y": 4,
      "z": 2,
      "name": "Rock_Stone"
    },
    {
      "x": -7,
      "y": 5,
      "z": 2,
      "name": "Rock_Stone"
    },
    {
      "x": -7,
      "y": 6,
      "z": 2,
      "name": "Rock_Stone"
    },
    {
      "x": -7,
      "y": 7,
      "z": 2,
      "name": "Rock_Stone"
    },
    {
      "x": -7,
      "y": 8,
      "z": 2,
      "name": "Rock_Stone"
    },
    {
      "x": -7,
      "y": 9,
      "z": 2,
      "name": "Rock_Stone"
    },
    {
      "x": -7,
      "y": 10,
      "z": 2,
      "name": "Rock_Stone"
    },
    {
      "x": -7,
      "y": 11,
      "z": 2,
      "name": "Rock_Stone"
    },
    {
      "x": -7,
      "y": 12,
      "z": 2,
      "name": "Rock_Stone"
    },
    {
      "x": -7,
      "y": 13,
      "z": 2,
      "name": "Soil_Dirt"
    },
    {
      "x": -7,
      "y": 14,
      "z": 2,
      "name": "Soil_Dirt"
    },
    {
      "x": -7,
      "y": 15,
      "z": 2,
      "name": "Soil_Dirt"
    },
    {
      "x": -7,
      "y": 16,
      "z": 2,
      "name": "Soil_Grass"
    },
    {
      "x": -7,
      "y": 0,
      "z": 3,
      "name": "Rock_Stone"
    },
    {
      "x": -7,
      "y": 1,
      "z": 3,
      "name": "Rock_Stone"
    },
    {
      "x": -7,
      "y": 2,
      "z": 3,
      "name": "Rock_Stone"
    },
    {
      "x": -7,
      "y": 3,
      "z": 3,
      "name": "Rock_Stone"
    },
    {
      "x": -7,
      "y": 4,
      "z": 3,
      "name": "Rock_Stone"
    },
    {
      "x": -7,
      "y": 5,
      "z": 3,
      "name": "Rock_Stone"
    },
    {
      "x": -7,
      "y": 6,
      "z": 3,
      "name": "Rock_Stone"
    },
    {
      "x": -7,
      "y": 7,
      "z": 3,
      "name": "Rock_Stone"
    },
    {
      "x": -7,
      "y": 8,
      "z": 3,
      "name": "Rock_Stone"
    },
    {
      "x": -7,
      "y": 9,
      "z": 3,
      "name": "Rock_Stone"
    },
    {
      "x": -7,
      "y": 10,
      "z": 3,
      "name": "Rock_Stone"
    },
    {
      "x": -7,
      "y": 11,
      "z": 3,
      "name": "Rock_Stone"
    },
    {
      "x": -7,
      "y": 12,
      "z": 3,
      "name": "Rock_Stone"
    },
    {
      "x": -7,
      "y": 13,
      "z": 3,
      "name": "Soil_Dirt"
    },
    {
      "x": -7,
      "y": 14,
      "z": 3,
      "name": "Soil_Dirt"
    },
    {
      "x": -7,
      "y": 15,
      "z": 3,
      "name": "Soil_Dirt"
    },
    {
      "x": -7,
      "y": 16,
      "z": 3,
      "name": "Soil_Grass"
    },
    {
      "x": -7,
      "y": 0,
      "z": 4,
      "name": "Rock_Stone"
    },
    {
      "x": -7,
      "y": 1,
      "z": 4,
      "name": "Rock_Stone"
    },
    {
      "x": -7,
      "y": 2,
      "z": 4,
      "name": "Rock_Stone"
    },
    {
      "x": -7,
      "y": 3,
      "z": 4,
      "name": "Rock_Stone"
    },
    {
      "x": -7,
      "y": 4,
      "z": 4,
      "name": "Rock_Stone"
    },
    {
      "x": -7,
      "y": 5,
      "z": 4,
      "name": "Rock_Stone"
    },
    {
      "x": -7,
      "y": 6,
      "z": 4,
      "name": "Rock_Stone"
    },
    {
      "x": -7,
      "y": 7,
      "z": 4,
      "name": "Rock_Stone"
    },
    {
      "x": -7,
      "y": 8,
      "z": 4,
      "name": "Rock_Stone"
    },
    {
      "x": -7,
      "y": 9,
      "z": 4,
      "name": "Rock_Stone"
    },
    {
      "x": -7,
      "y": 10,
      "z": 4,
      "name": "Rock_Stone"
    },
    {
      "x": -7,
      "y": 11,
      "z": 4,
      "name": "Rock_Stone"
    },
    {
      "x": -7,
      "y": 12,
      "z": 4,
      "name": "Rock_Stone"
    },
    {
      "x": -7,
      "y": 13,
      "z": 4,
      "name": "Soil_Dirt"
    },
    {
      "x": -7,
      "y": 14,
      "z": 4,
      "name": "Soil_Dirt"
    },
    {
      "x": -7,
      "y": 15,
      "z": 4,
      "name": "Soil_Dirt"
    },
    {
      "x": -7,
      "y": 16,
      "z": 4,
      "name": "Soil_Grass"
    },
    {
      "x": -7,
      "y": 0,
      "z": 5,
      "name": "Rock_Stone"
    },
    {
      "x": -7,
      "y": 1,
      "z": 5,
      "name": "Rock_Stone"
    },
    {
      "x": -7,
      "y": 2,
      "z": 5,
      "name": "Rock_Stone"
    },
    {
      "x": -7,
      "y": 3,
      "z": 5,
      "name": "Rock_Stone"
    },
    {
      "x": -7,
      "y": 4,
      "z": 5,
      "name": "Rock_Stone"
    },
    {
      "x": -7,
      "y": 5,
      "z": 5,
      "name": "Rock_Stone"
    },
    {
      "x": -7,
      "y": 6,
      "z": 5,
      "name": "Rock_Stone"
    },
    {
      "x": -7,
      "y": 7,
      "z": 5,
      "name": "Rock_Stone"
    },
    {
      "x": -7,
      "y": 8,
      "z": 5,
      "name": "Rock_Stone"
    },
    {
      "x": -7,
      "y": 9,
      "z": 5,
      "name": "Rock_Stone"
    },
    {
      "x": -7,
      "y": 10,
      "z": 5,
      "name": "Rock_Stone"
    },
    {
      "x": -7,
      "y": 11,
      "z": 5,
      "name": "Rock_Stone"
    },
    {
      "x": -7,
      "y": 12,
      "z": 5,
      "name": "Rock_Stone"
    },
    {
      "x": -7,
      "y": 13,
      "z": 5,
      "name": "Soil_Dirt"
    },
    {
      "x": -7,
      "y": 14,
      "z": 5,
      "name": "Soil_Dirt"
    },
    {
      "x": -7,
      "y": 15,
      "z": 5,
      "name": "Soil_Dirt"
    },
    {
      "x": -7,
      "y": 16,
      "z": 5,
      "name": "Soil_Grass"
    },
    {
      "x": -7,
      "y": 0,
      "z": 6,
      "name": "Rock_Stone"
    },
    {
      "x": -7,
      "y": 1,
      "z": 6,
      "name": "Rock_Stone"
    },
    {
      "x": -7,
      "y": 2,
      "z": 6,
      "name": "Rock_Stone"
    },
    {
      "x": -7,
      "y": 3,
      "z": 6,
      "name": "Rock_Stone"
    },
    {
      "x": -7,
      "y": 4,
      "z": 6,
      "name": "Rock_Stone"
    },
    {
      "x": -7,
      "y": 5,
      "z": 6,
      "name": "Rock_Stone"
    },
    {
      "x": -7,
      "y": 6,
      "z": 6,
      "name": "Rock_Stone"
    },
    {
      "x": -7,
      "y": 7,
      "z": 6,
      "name": "Rock_Stone"
    },
    {
      "x": -7,
      "y": 8,
      "z": 6,
      "name": "Rock_Stone"
    },
    {
      "x": -7,
      "y": 9,
      "z": 6,
      "name": "Rock_Stone"
    },
    {
      "x": -7,
      "y": 10,
      "z": 6,
      "name": "Rock_Stone"
    },
    {
      "x": -7,
      "y": 11,
      "z": 6,
      "name": "Rock_Stone"
    },
    {
      "x": -7,
      "y": 12,
      "z": 6,
      "name": "Rock_Stone"
    },
    {
      "x": -7,
      "y": 13,
      "z": 6,
      "name": "Soil_Dirt"
    },
    {
      "x": -7,
      "y": 14,
      "z": 6,
      "name": "Soil_Dirt"
    },
    {
      "x": -7,
      "y": 15,
      "z": 6,
      "name": "Soil_Dirt"
    },
    {
      "x": -7,
      "y": 16,
      "z": 6,
      "name": "Soil_Grass"
    },
    {
      "x": -7,
      "y": 0,
      "z": 7,
      "name": "Rock_Stone"
    },
    {
      "x": -7,
      "y": 1,
      "z": 7,
      "name": "Rock_Stone"
    },
    {
      "x": -7,
      "y": 2,
      "z": 7,
      "name": "Rock_Stone"
    },
    {
      "x": -7,
      "y": 3,
      "z": 7,
      "name": "Rock_Stone"
    },
    {
      "x": -7,
      "y": 4,
      "z": 7,
      "name": "Rock_Stone"
    },
    {
      "x": -7,
      "y": 5,
      "z": 7,
      "name": "Rock_Stone"
    },
    {
      "x": -7,
      "y": 6,
      "z": 7,
      "name": "Rock_Stone"
    },
    {
      "x": -7,
      "y": 7,
      "z": 7,
      "name": "Rock_Stone"
    },
    {
      "x": -7,
      "y": 8,
      "z": 7,
      "name": "Rock_Stone"
    },
    {
      "x": -7,
      "y": 9,
      "z": 7,
      "name": "Rock_Stone"
    },
    {
      "x": -7,
      "y": 10,
      "z": 7,
      "name": "Rock_Stone"
    },
    {
      "x": -7,
      "y": 11,
      "z": 7,
      "name": "Rock_Stone"
    },
    {
      "x": -7,
      "y": 12,
      "z": 7,
      "name": "Rock_Stone"
    },
    {
      "x": -7,
      "y": 13,
      "z": 7,
      "name": "Soil_Dirt"
    },
    {
      "x": -7,
      "y": 14,
      "z": 7,
      "name": "Soil_Dirt"
    },
    {
      "x": -7,
      "y": 15,
      "z": 7,
      "name": "Soil_Dirt"
    },
    {
      "x": -7,
      "y": 16,
      "z": 7,
      "name": "Soil_Grass"
    },
    {
      "x": -7,
      "y": 0,
      "z": 8,
      "name": "Rock_Stone"
    },
    {
      "x": -7,
      "y": 1,
      "z": 8,
      "name": "Rock_Stone"
    },
    {
      "x": -7,
      "y": 2,
      "z": 8,
      "name": "Rock_Stone"
    },
    {
      "x": -7,
      "y": 3,
      "z": 8,
      "name": "Rock_Stone"
    },
    {
      "x": -7,
      "y": 4,
      "z": 8,
      "name": "Rock_Stone"
    },
    {
      "x": -7,
      "y": 5,
      "z": 8,
      "name": "Rock_Stone"
    },
    {
      "x": -7,
      "y": 6,
      "z": 8,
      "name": "Rock_Stone"
    },
    {
      "x": -7,
      "y": 7,
      "z": 8,
      "name": "Rock_Stone"
    },
    {
      "x": -7,
      "y": 8,
      "z": 8,
      "name": "Rock_Stone"
    },
    {
      "x": -7,
      "y": 9,
      "z": 8,
      "name": "Rock_Stone"
    },
    {
      "x": -7,
      "y": 10,
      "z": 8,
      "name": "Rock_Stone"
    },
    {
      "x": -7,
      "y": 11,
      "z": 8,
      "name": "Rock_Stone"
    },
    {
      "x": -7,
      "y": 12,
      "z": 8,
      "name": "Rock_Stone"
    },
    {
      "x": -7,
      "y": 13,
      "z": 8,
      "name": "Soil_Dirt"
    },
    {
      "x": -7,
      "y": 14,
      "z": 8,
      "name": "Soil_Dirt"
    },
    {
      "x": -7,
      "y": 15,
      "z": 8,
      "name": "Soil_Dirt"
    },
    {
      "x": -7,
      "y": 16,
      "z": 8,
      "name": "Soil_Grass"
    },
    {
      "x": -6,
      "y": 0,
      "z": -7,
      "name": "Rock_Stone"
    },
    {
      "x": -6,
      "y": 1,
      "z": -7,
      "name": "Rock_Stone"
    },
    {
      "x": -6,
      "y": 2,
      "z": -7,
      "name": "Rock_Stone"
    },
    {
      "x": -6,
      "y": 3,
      "z": -7,
      "name": "Rock_Stone"
    },
    {
      "x": -6,
      "y": 4,
      "z": -7,
      "name": "Rock_Stone"
    },
    {
      "x": -6,
      "y": 5,
      "z": -7,
      "name": "Rock_Stone"
    },
    {
      "x": -6,
      "y": 6,
      "z": -7,
      "name": "Rock_Stone"
    },
    {
      "x": -6,
      "y": 7,
      "z": -7,
      "name": "Rock_Stone"
    },
    {
      "x": -6,
      "y": 8,
      "z": -7,
      "name": "Rock_Stone"
    },
    {
      "x": -6,
      "y": 9,
      "z": -7,
      "name": "Rock_Stone"
    },
    {
      "x": -6,
      "y": 10,
      "z": -7,
      "name": "Rock_Stone"
    },
    {
      "x": -6,
      "y": 11,
      "z": -7,
      "name": "Rock_Stone"
    },
    {
      "x": -6,
      "y": 12,
      "z": -7,
      "name": "Rock_Stone"
    },
    {
      "x": -6,
      "y": 13,
      "z": -7,
      "name": "Soil_Dirt"
    },
    {
      "x": -6,
      "y": 14,
      "z": -7,
      "name": "Soil_Dirt"
    },
    {
      "x": -6,
      "y": 15,
      "z": -7,
      "name": "Soil_Dirt"
    },
    {
      "x": -6,
      "y": 16,
      "z": -7,
      "name": "Soil_Grass"
    },
    {
      "x": -6,
      "y": 0,
      "z": -6,
      "name": "Rock_Stone"
    },
    {
      "x": -6,
      "y": 1,
      "z": -6,
      "name": "Rock_Stone"
    },
    {
      "x": -6,
      "y": 2,
      "z": -6,
      "name": "Rock_Stone"
    },
    {
      "x": -6,
      "y": 3,
      "z": -6,
      "name": "Rock_Stone"
    },
    {
      "x": -6,
      "y": 4,
      "z": -6,
      "name": "Rock_Stone"
    },
    {
      "x": -6,
      "y": 5,
      "z": -6,
      "name": "Rock_Stone"
    },
    {
      "x": -6,
      "y": 6,
      "z": -6,
      "name": "Rock_Stone"
    },
    {
      "x": -6,
      "y": 7,
      "z": -6,
      "name": "Rock_Stone"
    },
    {
      "x": -6,
      "y": 8,
      "z": -6,
      "name": "Rock_Stone"
    },
    {
      "x": -6,
      "y": 9,
      "z": -6,
      "name": "Rock_Stone"
    },
    {
      "x": -6,
      "y": 10,
      "z": -6,
      "name": "Rock_Stone"
    },
    {
      "x": -6,
      "y": 11,
      "z": -6,
      "name": "Rock_Stone"
    },
    {
      "x": -6,
      "y": 12,
      "z": -6,
      "name": "Rock_Stone"
    },
    {
      "x": -6,
      "y": 13,
      "z": -6,
      "name": "Soil_Dirt"
    },
    {
      "x": -6,
      "y": 14,
      "z": -6,
      "name": "Soil_Dirt"
    },
    {
      "x": -6,
      "y": 15,
      "z": -6,
      "name": "Soil_Dirt"
    },
    {
      "x": -6,
      "y": 16,
      "z": -6,
      "name": "Wood_Softwood_Planks"
    },
    {
      "x": -6,
      "y": 23,
      "z": -6,
      "name": "Wood_Softwood_Roof_Shallow",
      "rotation": 3
    },
    {
      "x": -6,
      "y": 0,
      "z": -5,
      "name": "Rock_Stone"
    },
    {
      "x": -6,
      "y": 1,
      "z": -5,
      "name": "Rock_Stone"
    },
    {
      "x": -6,
      "y": 2,
      "z": -5,
      "name": "Rock_Stone"
    },
    {
      "x": -6,
      "y": 3,
      "z": -5,
      "name": "Rock_Stone"
    },
    {
      "x": -6,
      "y": 4,
      "z": -5,
      "name": "Rock_Stone"
    },
    {
      "x": -6,
      "y": 5,
      "z": -5,
      "name": "Rock_Stone"
    },
    {
      "x": -6,
      "y": 6,
      "z": -5,
      "name": "Rock_Stone"
    },
    {
      "x": -6,
      "y": 7,
      "z": -5,
      "name": "Rock_Stone"
    },
    {
      "x": -6,
      "y": 8,
      "z": -5,
      "name": "Rock_Stone"
    },
    {
      "x": -6,
      "y": 9,
      "z": -5,
      "name": "Rock_Stone"
    },
    {
      "x": -6,
      "y": 10,
      "z": -5,
      "name": "Rock_Stone"
    },
    {
      "x": -6,
      "y": 11,
      "z": -5,
      "name": "Rock_Stone"
    },
    {
      "x": -6,
      "y": 12,
      "z": -5,
      "name": "Rock_Stone"
    },
    {
      "x": -6,
      "y": 13,
      "z": -5,
      "name": "Soil_Dirt"
    },
    {
      "x": -6,
      "y": 14,
      "z": -5,
      "name": "Soil_Dirt"
    },
    {
      "x": -6,
      "y": 15,
      "z": -5,
      "name": "Soil_Dirt"
    },
    {
      "x": -6,
      "y": 16,
      "z": -5,
      "name": "Wood_Softwood_Planks"
    },
    {
      "x": -6,
      "y": 23,
      "z": -5,
      "name": "Wood_Softwood_Roof_Shallow",
      "rotation": 3
    },
    {
      "x": -6,
      "y": 0,
      "z": -4,
      "name": "Rock_Stone"
    },
    {
      "x": -6,
      "y": 1,
      "z": -4,
      "name": "Rock_Stone"
    },
    {
      "x": -6,
      "y": 2,
      "z": -4,
      "name": "Rock_Stone"
    },
    {
      "x": -6,
      "y": 3,
      "z": -4,
      "name": "Rock_Stone"
    },
    {
      "x": -6,
      "y": 4,
      "z": -4,
      "name": "Rock_Stone"
    },
    {
      "x": -6,
      "y": 5,
      "z": -4,
      "name": "Rock_Stone"
    },
    {
      "x": -6,
      "y": 6,
      "z": -4,
      "name": "Rock_Stone"
    },
    {
      "x": -6,
      "y": 7,
      "z": -4,
      "name": "Rock_Stone"
    },
    {
      "x": -6,
      "y": 8,
      "z": -4,
      "name": "Rock_Stone"
    },
    {
      "x": -6,
      "y": 9,
      "z": -4,
      "name": "Rock_Stone"
    },
    {
      "x": -6,
      "y": 10,
      "z": -4,
      "name": "Rock_Stone"
    },
    {
      "x": -6,
      "y": 11,
      "z": -4,
      "name": "Rock_Stone"
    },
    {
      "x": -6,
      "y": 12,
      "z": -4,
      "name": "Rock_Stone"
    },
    {
      "x": -6,
      "y": 13,
      "z": -4,
      "name": "Rock_Stone"
    },
    {
      "x": -6,
      "y": 14,
      "z": -4,
      "name": "Rock_Stone"
    },
    {
      "x": -6,
      "y": 15,
      "z": -4,
      "name": "Soil_Dirt"
    },
    {
      "x": -6,
      "y": 16,
      "z": -4,
      "name": "Wood_Softwood_Planks"
    },
    {
      "x": -6,
      "y": 23,
      "z": -4,
      "name": "*Wood_Softwood_Roof_Shallow_State_Definitions_Inverted_Corner_Right",
      "rotation": 3
    },
    {
      "x": -6,
      "y": 0,
      "z": -3,
      "name": "Rock_Stone"
    },
    {
      "x": -6,
      "y": 1,
      "z": -3,
      "name": "Rock_Stone"
    },
    {
      "x": -6,
      "y": 2,
      "z": -3,
      "name": "Rock_Stone"
    },
    {
      "x": -6,
      "y": 3,
      "z": -3,
      "name": "Rock_Stone"
    },
    {
      "x": -6,
      "y": 4,
      "z": -3,
      "name": "Rock_Stone"
    },
    {
      "x": -6,
      "y": 5,
      "z": -3,
      "name": "Rock_Stone"
    },
    {
      "x": -6,
      "y": 6,
      "z": -3,
      "name": "Rock_Stone"
    },
    {
      "x": -6,
      "y": 7,
      "z": -3,
      "name": "Rock_Stone"
    },
    {
      "x": -6,
      "y": 8,
      "z": -3,
      "name": "Rock_Stone"
    },
    {
      "x": -6,
      "y": 9,
      "z": -3,
      "name": "Rock_Stone"
    },
    {
      "x": -6,
      "y": 10,
      "z": -3,
      "name": "Rock_Stone"
    },
    {
      "x": -6,
      "y": 11,
      "z": -3,
      "name": "Rock_Stone"
    },
    {
      "x": -6,
      "y": 12,
      "z": -3,
      "name": "Rock_Stone"
    },
    {
      "x": -6,
      "y": 13,
      "z": -3,
      "name": "Rock_Stone"
    },
    {
      "x": -6,
      "y": 14,
      "z": -3,
      "name": "Rock_Stone"
    },
    {
      "x": -6,
      "y": 15,
      "z": -3,
      "name": "Soil_Dirt"
    },
    {
      "x": -6,
      "y": 16,
      "z": -3,
      "name": "Wood_Softwood_Planks"
    },
    {
      "x": -6,
      "y": 23,
      "z": -3,
      "name": "*Wood_Softwood_Roof_Shallow_State_Definitions_Inverted_Corner_Right",
      "filler": 32,
      "rotation": 3
    },
    {
      "x": -6,
      "y": 0,
      "z": -2,
      "name": "Rock_Stone"
    },
    {
      "x": -6,
      "y": 1,
      "z": -2,
      "name": "Rock_Stone"
    },
    {
      "x": -6,
      "y": 2,
      "z": -2,
      "name": "Rock_Stone"
    },
    {
      "x": -6,
      "y": 3,
      "z": -2,
      "name": "Rock_Stone"
    },
    {
      "x": -6,
      "y": 4,
      "z": -2,
      "name": "Rock_Stone"
    },
    {
      "x": -6,
      "y": 5,
      "z": -2,
      "name": "Rock_Stone"
    },
    {
      "x": -6,
      "y": 6,
      "z": -2,
      "name": "Rock_Stone"
    },
    {
      "x": -6,
      "y": 7,
      "z": -2,
      "name": "Rock_Stone"
    },
    {
      "x": -6,
      "y": 8,
      "z": -2,
      "name": "Rock_Stone"
    },
    {
      "x": -6,
      "y": 9,
      "z": -2,
      "name": "Rock_Stone"
    },
    {
      "x": -6,
      "y": 10,
      "z": -2,
      "name": "Rock_Stone"
    },
    {
      "x": -6,
      "y": 11,
      "z": -2,
      "name": "Rock_Stone"
    },
    {
      "x": -6,
      "y": 12,
      "z": -2,
      "name": "Rock_Stone"
    },
    {
      "x": -6,
      "y": 13,
      "z": -2,
      "name": "Rock_Stone"
    },
    {
      "x": -6,
      "y": 14,
      "z": -2,
      "name": "Rock_Stone"
    },
    {
      "x": -6,
      "y": 15,
      "z": -2,
      "name": "Soil_Dirt"
    },
    {
      "x": -6,
      "y": 16,
      "z": -2,
      "name": "Wood_Softwood_Planks"
    },
    {
      "x": -6,
      "y": 23,
      "z": -2,
      "name": "Wood_Softwood_Stairs",
      "rotation": 10
    },
    {
      "x": -6,
      "y": 24,
      "z": -2,
      "name": "Wood_Softwood_Roof_Shallow",
      "rotation": 2
    },
    {
      "x": -6,
      "y": 0,
      "z": -1,
      "name": "Rock_Stone"
    },
    {
      "x": -6,
      "y": 1,
      "z": -1,
      "name": "Rock_Stone"
    },
    {
      "x": -6,
      "y": 2,
      "z": -1,
      "name": "Rock_Stone"
    },
    {
      "x": -6,
      "y": 3,
      "z": -1,
      "name": "Rock_Stone"
    },
    {
      "x": -6,
      "y": 4,
      "z": -1,
      "name": "Rock_Stone"
    },
    {
      "x": -6,
      "y": 5,
      "z": -1,
      "name": "Rock_Stone"
    },
    {
      "x": -6,
      "y": 6,
      "z": -1,
      "name": "Rock_Stone"
    },
    {
      "x": -6,
      "y": 7,
      "z": -1,
      "name": "Rock_Stone"
    },
    {
      "x": -6,
      "y": 8,
      "z": -1,
      "name": "Rock_Stone"
    },
    {
      "x": -6,
      "y": 9,
      "z": -1,
      "name": "Rock_Stone"
    },
    {
      "x": -6,
      "y": 10,
      "z": -1,
      "name": "Rock_Stone"
    },
    {
      "x": -6,
      "y": 11,
      "z": -1,
      "name": "Rock_Stone"
    },
    {
      "x": -6,
      "y": 12,
      "z": -1,
      "name": "Rock_Stone"
    },
    {
      "x": -6,
      "y": 13,
      "z": -1,
      "name": "Rock_Stone"
    },
    {
      "x": -6,
      "y": 14,
      "z": -1,
      "name": "Rock_Stone"
    },
    {
      "x": -6,
      "y": 15,
      "z": -1,
      "name": "Soil_Dirt"
    },
    {
      "x": -6,
      "y": 16,
      "z": -1,
      "name": "Wood_Softwood_Planks"
    },
    {
      "x": -6,
      "y": 24,
      "z": -1,
      "name": "Wood_Softwood_Roof_Shallow",
      "filler": 32,
      "rotation": 2
    },
    {
      "x": -6,
      "y": 0,
      "z": 0,
      "name": "Rock_Stone"
    },
    {
      "x": -6,
      "y": 1,
      "z": 0,
      "name": "Rock_Stone"
    },
    {
      "x": -6,
      "y": 2,
      "z": 0,
      "name": "Rock_Stone"
    },
    {
      "x": -6,
      "y": 3,
      "z": 0,
      "name": "Rock_Stone"
    },
    {
      "x": -6,
      "y": 4,
      "z": 0,
      "name": "Rock_Stone"
    },
    {
      "x": -6,
      "y": 5,
      "z": 0,
      "name": "Rock_Stone"
    },
    {
      "x": -6,
      "y": 6,
      "z": 0,
      "name": "Rock_Stone"
    },
    {
      "x": -6,
      "y": 7,
      "z": 0,
      "name": "Rock_Stone"
    },
    {
      "x": -6,
      "y": 8,
      "z": 0,
      "name": "Rock_Stone"
    },
    {
      "x": -6,
      "y": 9,
      "z": 0,
      "name": "Rock_Stone"
    },
    {
      "x": -6,
      "y": 10,
      "z": 0,
      "name": "Rock_Stone"
    },
    {
      "x": -6,
      "y": 11,
      "z": 0,
      "name": "Rock_Stone"
    },
    {
      "x": -6,
      "y": 12,
      "z": 0,
      "name": "Rock_Stone"
    },
    {
      "x": -6,
      "y": 13,
      "z": 0,
      "name": "Rock_Stone"
    },
    {
      "x": -6,
      "y": 14,
      "z": 0,
      "name": "Rock_Stone"
    },
    {
      "x": -6,
      "y": 15,
      "z": 0,
      "name": "Soil_Dirt"
    },
    {
      "x": -6,
      "y": 16,
      "z": 0,
      "name": "Wood_Softwood_Planks"
    },
    {
      "x": -6,
      "y": 24,
      "z": 0,
      "name": "Wood_Softwood_Roof_Shallow",
      "filler": 992
    },
    {
      "x": -6,
      "y": 0,
      "z": 1,
      "name": "Rock_Stone"
    },
    {
      "x": -6,
      "y": 1,
      "z": 1,
      "name": "Rock_Stone"
    },
    {
      "x": -6,
      "y": 2,
      "z": 1,
      "name": "Rock_Stone"
    },
    {
      "x": -6,
      "y": 3,
      "z": 1,
      "name": "Rock_Stone"
    },
    {
      "x": -6,
      "y": 4,
      "z": 1,
      "name": "Rock_Stone"
    },
    {
      "x": -6,
      "y": 5,
      "z": 1,
      "name": "Rock_Stone"
    },
    {
      "x": -6,
      "y": 6,
      "z": 1,
      "name": "Rock_Stone"
    },
    {
      "x": -6,
      "y": 7,
      "z": 1,
      "name": "Rock_Stone"
    },
    {
      "x": -6,
      "y": 8,
      "z": 1,
      "name": "Rock_Stone"
    },
    {
      "x": -6,
      "y": 9,
      "z": 1,
      "name": "Rock_Stone"
    },
    {
      "x": -6,
      "y": 10,
      "z": 1,
      "name": "Rock_Stone"
    },
    {
      "x": -6,
      "y": 11,
      "z": 1,
      "name": "Rock_Stone"
    },
    {
      "x": -6,
      "y": 12,
      "z": 1,
      "name": "Rock_Stone"
    },
    {
      "x": -6,
      "y": 13,
      "z": 1,
      "name": "Rock_Stone"
    },
    {
      "x": -6,
      "y": 14,
      "z": 1,
      "name": "Rock_Stone"
    },
    {
      "x": -6,
      "y": 15,
      "z": 1,
      "name": "Soil_Dirt"
    },
    {
      "x": -6,
      "y": 16,
      "z": 1,
      "name": "Wood_Softwood_Planks"
    },
    {
      "x": -6,
      "y": 23,
      "z": 1,
      "name": "Wood_Softwood_Stairs",
      "rotation": 8
    },
    {
      "x": -6,
      "y": 24,
      "z": 1,
      "name": "Wood_Softwood_Roof_Shallow"
    },
    {
      "x": -6,
      "y": 0,
      "z": 2,
      "name": "Rock_Stone"
    },
    {
      "x": -6,
      "y": 1,
      "z": 2,
      "name": "Rock_Stone"
    },
    {
      "x": -6,
      "y": 2,
      "z": 2,
      "name": "Rock_Stone"
    },
    {
      "x": -6,
      "y": 3,
      "z": 2,
      "name": "Rock_Stone"
    },
    {
      "x": -6,
      "y": 4,
      "z": 2,
      "name": "Rock_Stone"
    },
    {
      "x": -6,
      "y": 5,
      "z": 2,
      "name": "Rock_Stone"
    },
    {
      "x": -6,
      "y": 6,
      "z": 2,
      "name": "Rock_Stone"
    },
    {
      "x": -6,
      "y": 7,
      "z": 2,
      "name": "Rock_Stone"
    },
    {
      "x": -6,
      "y": 8,
      "z": 2,
      "name": "Rock_Stone"
    },
    {
      "x": -6,
      "y": 9,
      "z": 2,
      "name": "Rock_Stone"
    },
    {
      "x": -6,
      "y": 10,
      "z": 2,
      "name": "Rock_Stone"
    },
    {
      "x": -6,
      "y": 11,
      "z": 2,
      "name": "Rock_Stone"
    },
    {
      "x": -6,
      "y": 12,
      "z": 2,
      "name": "Rock_Stone"
    },
    {
      "x": -6,
      "y": 13,
      "z": 2,
      "name": "Rock_Stone"
    },
    {
      "x": -6,
      "y": 14,
      "z": 2,
      "name": "Rock_Stone"
    },
    {
      "x": -6,
      "y": 15,
      "z": 2,
      "name": "Soil_Dirt"
    },
    {
      "x": -6,
      "y": 16,
      "z": 2,
      "name": "Wood_Softwood_Planks"
    },
    {
      "x": -6,
      "y": 23,
      "z": 2,
      "name": "Wood_Softwood_Roof_Shallow",
      "filler": 992
    },
    {
      "x": -6,
      "y": 0,
      "z": 3,
      "name": "Rock_Stone"
    },
    {
      "x": -6,
      "y": 1,
      "z": 3,
      "name": "Rock_Stone"
    },
    {
      "x": -6,
      "y": 2,
      "z": 3,
      "name": "Rock_Stone"
    },
    {
      "x": -6,
      "y": 3,
      "z": 3,
      "name": "Rock_Stone"
    },
    {
      "x": -6,
      "y": 4,
      "z": 3,
      "name": "Rock_Stone"
    },
    {
      "x": -6,
      "y": 5,
      "z": 3,
      "name": "Rock_Stone"
    },
    {
      "x": -6,
      "y": 6,
      "z": 3,
      "name": "Rock_Stone"
    },
    {
      "x": -6,
      "y": 7,
      "z": 3,
      "name": "Rock_Stone"
    },
    {
      "x": -6,
      "y": 8,
      "z": 3,
      "name": "Rock_Stone"
    },
    {
      "x": -6,
      "y": 9,
      "z": 3,
      "name": "Rock_Stone"
    },
    {
      "x": -6,
      "y": 10,
      "z": 3,
      "name": "Rock_Stone"
    },
    {
      "x": -6,
      "y": 11,
      "z": 3,
      "name": "Rock_Stone"
    },
    {
      "x": -6,
      "y": 12,
      "z": 3,
      "name": "Rock_Stone"
    },
    {
      "x": -6,
      "y": 13,
      "z": 3,
      "name": "Rock_Stone"
    },
    {
      "x": -6,
      "y": 14,
      "z": 3,
      "name": "Rock_Stone"
    },
    {
      "x": -6,
      "y": 15,
      "z": 3,
      "name": "Soil_Dirt"
    },
    {
      "x": -6,
      "y": 16,
      "z": 3,
      "name": "Wood_Softwood_Planks"
    },
    {
      "x": -6,
      "y": 22,
      "z": 3,
      "name": "Wood_Softwood_Stairs",
      "rotation": 8
    },
    {
      "x": -6,
      "y": 23,
      "z": 3,
      "name": "Wood_Softwood_Roof_Shallow"
    },
    {
      "x": -6,
      "y": 0,
      "z": 4,
      "name": "Rock_Stone"
    },
    {
      "x": -6,
      "y": 1,
      "z": 4,
      "name": "Rock_Stone"
    },
    {
      "x": -6,
      "y": 2,
      "z": 4,
      "name": "Rock_Stone"
    },
    {
      "x": -6,
      "y": 3,
      "z": 4,
      "name": "Rock_Stone"
    },
    {
      "x": -6,
      "y": 4,
      "z": 4,
      "name": "Rock_Stone"
    },
    {
      "x": -6,
      "y": 5,
      "z": 4,
      "name": "Rock_Stone"
    },
    {
      "x": -6,
      "y": 6,
      "z": 4,
      "name": "Rock_Stone"
    },
    {
      "x": -6,
      "y": 7,
      "z": 4,
      "name": "Rock_Stone"
    },
    {
      "x": -6,
      "y": 8,
      "z": 4,
      "name": "Rock_Stone"
    },
    {
      "x": -6,
      "y": 9,
      "z": 4,
      "name": "Rock_Stone"
    },
    {
      "x": -6,
      "y": 10,
      "z": 4,
      "name": "Rock_Stone"
    },
    {
      "x": -6,
      "y": 11,
      "z": 4,
      "name": "Rock_Stone"
    },
    {
      "x": -6,
      "y": 12,
      "z": 4,
      "name": "Rock_Stone"
    },
    {
      "x": -6,
      "y": 13,
      "z": 4,
      "name": "Soil_Dirt"
    },
    {
      "x": -6,
      "y": 14,
      "z": 4,
      "name": "Soil_Dirt"
    },
    {
      "x": -6,
      "y": 15,
      "z": 4,
      "name": "Soil_Dirt"
    },
    {
      "x": -6,
      "y": 16,
      "z": 4,
      "name": "Wood_Softwood_Planks"
    },
    {
      "x": -6,
      "y": 22,
      "z": 4,
      "name": "*Wood_Softwood_Roof_Shallow_State_Definitions_Inverted_Corner_Left",
      "filler": 992,
      "rotation": 3
    },
    {
      "x": -6,
      "y": 0,
      "z": 5,
      "name": "Rock_Stone"
    },
    {
      "x": -6,
      "y": 1,
      "z": 5,
      "name": "Rock_Stone"
    },
    {
      "x": -6,
      "y": 2,
      "z": 5,
      "name": "Rock_Stone"
    },
    {
      "x": -6,
      "y": 3,
      "z": 5,
      "name": "Rock_Stone"
    },
    {
      "x": -6,
      "y": 4,
      "z": 5,
      "name": "Rock_Stone"
    },
    {
      "x": -6,
      "y": 5,
      "z": 5,
      "name": "Rock_Stone"
    },
    {
      "x": -6,
      "y": 6,
      "z": 5,
      "name": "Rock_Stone"
    },
    {
      "x": -6,
      "y": 7,
      "z": 5,
      "name": "Rock_Stone"
    },
    {
      "x": -6,
      "y": 8,
      "z": 5,
      "name": "Rock_Stone"
    },
    {
      "x": -6,
      "y": 9,
      "z": 5,
      "name": "Rock_Stone"
    },
    {
      "x": -6,
      "y": 10,
      "z": 5,
      "name": "Rock_Stone"
    },
    {
      "x": -6,
      "y": 11,
      "z": 5,
      "name": "Rock_Stone"
    },
    {
      "x": -6,
      "y": 12,
      "z": 5,
      "name": "Rock_Stone"
    },
    {
      "x": -6,
      "y": 13,
      "z": 5,
      "name": "Soil_Dirt"
    },
    {
      "x": -6,
      "y": 14,
      "z": 5,
      "name": "Soil_Dirt"
    },
    {
      "x": -6,
      "y": 15,
      "z": 5,
      "name": "Soil_Dirt"
    },
    {
      "x": -6,
      "y": 16,
      "z": 5,
      "name": "Wood_Softwood_Planks"
    },
    {
      "x": -6,
      "y": 22,
      "z": 5,
      "name": "*Wood_Softwood_Roof_Shallow_State_Definitions_Inverted_Corner_Left",
      "rotation": 3
    },
    {
      "x": -6,
      "y": 0,
      "z": 6,
      "name": "Rock_Stone"
    },
    {
      "x": -6,
      "y": 1,
      "z": 6,
      "name": "Rock_Stone"
    },
    {
      "x": -6,
      "y": 2,
      "z": 6,
      "name": "Rock_Stone"
    },
    {
      "x": -6,
      "y": 3,
      "z": 6,
      "name": "Rock_Stone"
    },
    {
      "x": -6,
      "y": 4,
      "z": 6,
      "name": "Rock_Stone"
    },
    {
      "x": -6,
      "y": 5,
      "z": 6,
      "name": "Rock_Stone"
    },
    {
      "x": -6,
      "y": 6,
      "z": 6,
      "name": "Rock_Stone"
    },
    {
      "x": -6,
      "y": 7,
      "z": 6,
      "name": "Rock_Stone"
    },
    {
      "x": -6,
      "y": 8,
      "z": 6,
      "name": "Rock_Stone"
    },
    {
      "x": -6,
      "y": 9,
      "z": 6,
      "name": "Rock_Stone"
    },
    {
      "x": -6,
      "y": 10,
      "z": 6,
      "name": "Rock_Stone"
    },
    {
      "x": -6,
      "y": 11,
      "z": 6,
      "name": "Rock_Stone"
    },
    {
      "x": -6,
      "y": 12,
      "z": 6,
      "name": "Rock_Stone"
    },
    {
      "x": -6,
      "y": 13,
      "z": 6,
      "name": "Soil_Dirt"
    },
    {
      "x": -6,
      "y": 14,
      "z": 6,
      "name": "Soil_Dirt"
    },
    {
      "x": -6,
      "y": 15,
      "z": 6,
      "name": "Soil_Dirt"
    },
    {
      "x": -6,
      "y": 16,
      "z": 6,
      "name": "Wood_Softwood_Planks"
    },
    {
      "x": -6,
      "y": 22,
      "z": 6,
      "name": "Wood_Softwood_Roof_Shallow",
      "rotation": 3
    },
    {
      "x": -6,
      "y": 0,
      "z": 7,
      "name": "Rock_Stone"
    },
    {
      "x": -6,
      "y": 1,
      "z": 7,
      "name": "Rock_Stone"
    },
    {
      "x": -6,
      "y": 2,
      "z": 7,
      "name": "Rock_Stone"
    },
    {
      "x": -6,
      "y": 3,
      "z": 7,
      "name": "Rock_Stone"
    },
    {
      "x": -6,
      "y": 4,
      "z": 7,
      "name": "Rock_Stone"
    },
    {
      "x": -6,
      "y": 5,
      "z": 7,
      "name": "Rock_Stone"
    },
    {
      "x": -6,
      "y": 6,
      "z": 7,
      "name": "Rock_Stone"
    },
    {
      "x": -6,
      "y": 7,
      "z": 7,
      "name": "Rock_Stone"
    },
    {
      "x": -6,
      "y": 8,
      "z": 7,
      "name": "Rock_Stone"
    },
    {
      "x": -6,
      "y": 9,
      "z": 7,
      "name": "Rock_Stone"
    },
    {
      "x": -6,
      "y": 10,
      "z": 7,
      "name": "Rock_Stone"
    },
    {
      "x": -6,
      "y": 11,
      "z": 7,
      "name": "Rock_Stone"
    },
    {
      "x": -6,
      "y": 12,
      "z": 7,
      "name": "Rock_Stone"
    },
    {
      "x": -6,
      "y": 13,
      "z": 7,
      "name": "Soil_Dirt"
    },
    {
      "x": -6,
      "y": 14,
      "z": 7,
      "name": "Soil_Dirt"
    },
    {
      "x": -6,
      "y": 15,
      "z": 7,
      "name": "Soil_Dirt"
    },
    {
      "x": -6,
      "y": 16,
      "z": 7,
      "name": "Wood_Softwood_Planks"
    },
    {
      "x": -6,
      "y": 22,
      "z": 7,
      "name": "Wood_Softwood_Roof_Shallow",
      "rotation": 3
    },
    {
      "x": -6,
      "y": 0,
      "z": 8,
      "name": "Rock_Stone"
    },
    {
      "x": -6,
      "y": 1,
      "z": 8,
      "name": "Rock_Stone"
    },
    {
      "x": -6,
      "y": 2,
      "z": 8,
      "name": "Rock_Stone"
    },
    {
      "x": -6,
      "y": 3,
      "z": 8,
      "name": "Rock_Stone"
    },
    {
      "x": -6,
      "y": 4,
      "z": 8,
      "name": "Rock_Stone"
    },
    {
      "x": -6,
      "y": 5,
      "z": 8,
      "name": "Rock_Stone"
    },
    {
      "x": -6,
      "y": 6,
      "z": 8,
      "name": "Rock_Stone"
    },
    {
      "x": -6,
      "y": 7,
      "z": 8,
      "name": "Rock_Stone"
    },
    {
      "x": -6,
      "y": 8,
      "z": 8,
      "name": "Rock_Stone"
    },
    {
      "x": -6,
      "y": 9,
      "z": 8,
      "name": "Rock_Stone"
    },
    {
      "x": -6,
      "y": 10,
      "z": 8,
      "name": "Rock_Stone"
    },
    {
      "x": -6,
      "y": 11,
      "z": 8,
      "name": "Rock_Stone"
    },
    {
      "x": -6,
      "y": 12,
      "z": 8,
      "name": "Rock_Stone"
    },
    {
      "x": -6,
      "y": 13,
      "z": 8,
      "name": "Soil_Dirt"
    },
    {
      "x": -6,
      "y": 14,
      "z": 8,
      "name": "Soil_Dirt"
    },
    {
      "x": -6,
      "y": 15,
      "z": 8,
      "name": "Soil_Dirt"
    },
    {
      "x": -6,
      "y": 16,
      "z": 8,
      "name": "Soil_Grass"
    },
    {
      "x": -5,
      "y": 0,
      "z": -7,
      "name": "Rock_Stone"
    },
    {
      "x": -5,
      "y": 1,
      "z": -7,
      "name": "Rock_Stone"
    },
    {
      "x": -5,
      "y": 2,
      "z": -7,
      "name": "Rock_Stone"
    },
    {
      "x": -5,
      "y": 3,
      "z": -7,
      "name": "Rock_Stone"
    },
    {
      "x": -5,
      "y": 4,
      "z": -7,
      "name": "Rock_Stone"
    },
    {
      "x": -5,
      "y": 5,
      "z": -7,
      "name": "Rock_Stone"
    },
    {
      "x": -5,
      "y": 6,
      "z": -7,
      "name": "Rock_Stone"
    },
    {
      "x": -5,
      "y": 7,
      "z": -7,
      "name": "Rock_Stone"
    },
    {
      "x": -5,
      "y": 8,
      "z": -7,
      "name": "Rock_Stone"
    },
    {
      "x": -5,
      "y": 9,
      "z": -7,
      "name": "Rock_Stone"
    },
    {
      "x": -5,
      "y": 10,
      "z": -7,
      "name": "Rock_Stone"
    },
    {
      "x": -5,
      "y": 11,
      "z": -7,
      "name": "Rock_Stone"
    },
    {
      "x": -5,
      "y": 12,
      "z": -7,
      "name": "Rock_Stone"
    },
    {
      "x": -5,
      "y": 13,
      "z": -7,
      "name": "Soil_Dirt"
    },
    {
      "x": -5,
      "y": 14,
      "z": -7,
      "name": "Soil_Dirt"
    },
    {
      "x": -5,
      "y": 15,
      "z": -7,
      "name": "Soil_Dirt"
    },
    {
      "x": -5,
      "y": 16,
      "z": -7,
      "name": "Soil_Grass"
    },
    {
      "x": -5,
      "y": 0,
      "z": -6,
      "name": "Rock_Stone"
    },
    {
      "x": -5,
      "y": 1,
      "z": -6,
      "name": "Rock_Stone"
    },
    {
      "x": -5,
      "y": 2,
      "z": -6,
      "name": "Rock_Stone"
    },
    {
      "x": -5,
      "y": 3,
      "z": -6,
      "name": "Rock_Stone"
    },
    {
      "x": -5,
      "y": 4,
      "z": -6,
      "name": "Rock_Stone"
    },
    {
      "x": -5,
      "y": 5,
      "z": -6,
      "name": "Rock_Stone"
    },
    {
      "x": -5,
      "y": 6,
      "z": -6,
      "name": "Rock_Stone"
    },
    {
      "x": -5,
      "y": 7,
      "z": -6,
      "name": "Rock_Stone"
    },
    {
      "x": -5,
      "y": 8,
      "z": -6,
      "name": "Rock_Stone"
    },
    {
      "x": -5,
      "y": 9,
      "z": -6,
      "name": "Rock_Stone"
    },
    {
      "x": -5,
      "y": 10,
      "z": -6,
      "name": "Rock_Stone"
    },
    {
      "x": -5,
      "y": 11,
      "z": -6,
      "name": "Rock_Stone"
    },
    {
      "x": -5,
      "y": 12,
      "z": -6,
      "name": "Rock_Stone"
    },
    {
      "x": -5,
      "y": 13,
      "z": -6,
      "name": "Soil_Dirt"
    },
    {
      "x": -5,
      "y": 14,
      "z": -6,
      "name": "Soil_Dirt"
    },
    {
      "x": -5,
      "y": 15,
      "z": -6,
      "name": "Soil_Dirt"
    },
    {
      "x": -5,
      "y": 16,
      "z": -6,
      "name": "Wood_Softwood_Planks"
    },
    {
      "x": -5,
      "y": 23,
      "z": -6,
      "name": "Wood_Softwood_Roof_Shallow",
      "filler": 1,
      "rotation": 3
    },
    {
      "x": -5,
      "y": 0,
      "z": -5,
      "name": "Wood_Fir_Trunk",
      "support": 15
    },
    {
      "x": -5,
      "y": 1,
      "z": -5,
      "name": "Wood_Fir_Trunk",
      "support": 15
    },
    {
      "x": -5,
      "y": 2,
      "z": -5,
      "name": "Wood_Fir_Trunk",
      "support": 15
    },
    {
      "x": -5,
      "y": 3,
      "z": -5,
      "name": "Wood_Fir_Trunk",
      "support": 15
    },
    {
      "x": -5,
      "y": 4,
      "z": -5,
      "name": "Wood_Fir_Trunk",
      "support": 15
    },
    {
      "x": -5,
      "y": 5,
      "z": -5,
      "name": "Wood_Fir_Trunk",
      "support": 15
    },
    {
      "x": -5,
      "y": 6,
      "z": -5,
      "name": "Wood_Fir_Trunk",
      "support": 15
    },
    {
      "x": -5,
      "y": 7,
      "z": -5,
      "name": "Wood_Fir_Trunk",
      "support": 15
    },
    {
      "x": -5,
      "y": 8,
      "z": -5,
      "name": "Wood_Fir_Trunk",
      "support": 15
    },
    {
      "x": -5,
      "y": 9,
      "z": -5,
      "name": "Wood_Fir_Trunk",
      "support": 15
    },
    {
      "x": -5,
      "y": 10,
      "z": -5,
      "name": "Wood_Fir_Trunk",
      "support": 15,
      "rotation": 4
    },
    {
      "x": -5,
      "y": 11,
      "z": -5,
      "name": "Wood_Fir_Trunk",
      "support": 15
    },
    {
      "x": -5,
      "y": 12,
      "z": -5,
      "name": "Wood_Fir_Trunk",
      "support": 15
    },
    {
      "x": -5,
      "y": 13,
      "z": -5,
      "name": "Wood_Fir_Trunk",
      "support": 15
    },
    {
      "x": -5,
      "y": 14,
      "z": -5,
      "name": "Wood_Fir_Trunk",
      "support": 15
    },
    {
      "x": -5,
      "y": 15,
      "z": -5,
      "name": "Wood_Fir_Trunk",
      "support": 15
    },
    {
      "x": -5,
      "y": 16,
      "z": -5,
      "name": "Wood_Fir_Trunk",
      "support": 15
    },
    {
      "x": -5,
      "y": 17,
      "z": -5,
      "name": "Wood_Fir_Trunk",
      "support": 15
    },
    {
      "x": -5,
      "y": 18,
      "z": -5,
      "name": "Wood_Fir_Trunk",
      "support": 15
    },
    {
      "x": -5,
      "y": 19,
      "z": -5,
      "name": "Wood_Fir_Trunk",
      "support": 15
    },
    {
      "x": -5,
      "y": 20,
      "z": -5,
      "name": "Wood_Fir_Trunk",
      "support": 15
    },
    {
      "x": -5,
      "y": 21,
      "z": -5,
      "name": "Wood_Fir_Trunk",
      "support": 15
    },
    {
      "x": -5,
      "y": 22,
      "z": -5,
      "name": "Wood_Fir_Trunk",
      "support": 15
    },
    {
      "x": -5,
      "y": 23,
      "z": -5,
      "name": "Wood_Softwood_Roof_Shallow",
      "filler": 1,
      "rotation": 3
    },
    {
      "x": -5,
      "y": 0,
      "z": -4,
      "name": "Rock_Stone"
    },
    {
      "x": -5,
      "y": 3,
      "z": -4,
      "name": "Wood_Fir_Trunk",
      "support": 15,
      "rotation": 4
    },
    {
      "x": -5,
      "y": 4,
      "z": -4,
      "name": "Wood_Softwood_Planks"
    },
    {
      "x": -5,
      "y": 10,
      "z": -4,
      "name": "Wood_Fir_Trunk",
      "support": 15,
      "rotation": 4
    },
    {
      "x": -5,
      "y": 15,
      "z": -4,
      "name": "Wood_Fir_Trunk",
      "support": 15,
      "rotation": 4
    },
    {
      "x": -5,
      "y": 16,
      "z": -4,
      "name": "Wood_Softwood_Planks"
    },
    {
      "x": -5,
      "y": 17,
      "z": -4,
      "name": "Wood_Softwood_Fence_Gate",
      "rotation": 3
    },
    {
      "x": -5,
      "y": 21,
      "z": -4,
      "name": "Wood_Fir_Trunk",
      "support": 15,
      "rotation": 4
    },
    {
      "x": -5,
      "y": 23,
      "z": -4,
      "name": "*Wood_Softwood_Roof_Shallow_State_Definitions_Inverted_Corner_Right",
      "filler": 1,
      "rotation": 3
    },
    {
      "x": -5,
      "y": 0,
      "z": -3,
      "name": "Rock_Stone"
    },
    {
      "x": -5,
      "y": 3,
      "z": -3,
      "name": "Wood_Fir_Trunk",
      "support": 15,
      "rotation": 4
    },
    {
      "x": -5,
      "y": 4,
      "z": -3,
      "name": "Wood_Softwood_Planks"
    },
    {
      "x": -5,
      "y": 10,
      "z": -3,
      "name": "Wood_Fir_Trunk",
      "support": 15,
      "rotation": 4
    },
    {
      "x": -5,
      "y": 15,
      "z": -3,
      "name": "Wood_Fir_Trunk",
      "support": 15,
      "rotation": 4
    },
    {
      "x": -5,
      "y": 16,
      "z": -3,
      "name": "Wood_Softwood_Planks"
    },
    {
      "x": -5,
      "y": 17,
      "z": -3,
      "name": "Wood_Softwood_Fence_Gate",
      "rotation": 1
    },
    {
      "x": -5,
      "y": 21,
      "z": -3,
      "name": "Wood_Fir_Trunk",
      "support": 15,
      "rotation": 4
    },
    {
      "x": -5,
      "y": 23,
      "z": -3,
      "name": "*Wood_Softwood_Roof_Shallow_State_Definitions_Inverted_Corner_Right",
      "filler": 33,
      "rotation": 3
    },
    {
      "x": -5,
      "y": 0,
      "z": -2,
      "name": "Rock_Stone"
    },
    {
      "x": -5,
      "y": 3,
      "z": -2,
      "name": "Wood_Fir_Trunk",
      "support": 15,
      "rotation": 4
    },
    {
      "x": -5,
      "y": 4,
      "z": -2,
      "name": "Wood_Softwood_Stairs"
    },
    {
      "x": -5,
      "y": 10,
      "z": -2,
      "name": "Wood_Fir_Trunk",
      "support": 15,
      "rotation": 4
    },
    {
      "x": -5,
      "y": 15,
      "z": -2,
      "name": "Wood_Fir_Trunk",
      "support": 15,
      "rotation": 4
    },
    {
      "x": -5,
      "y": 16,
      "z": -2,
      "name": "Wood_Softwood_Planks"
    },
    {
      "x": -5,
      "y": 17,
      "z": -2,
      "name": "Wood_Softwood_Fence_Gate",
      "rotation": 3
    },
    {
      "x": -5,
      "y": 20,
      "z": -2,
      "name": "Deco_Lantern_Ceiling"
    },
    {
      "x": -5,
      "y": 21,
      "z": -2,
      "name": "Wood_Fir_Trunk",
      "support": 15,
      "rotation": 4
    },
    {
      "x": -5,
      "y": 23,
      "z": -2,
      "name": "Wood_Softwood_Stairs",
      "rotation": 10
    },
    {
      "x": -5,
      "y": 24,
      "z": -2,
      "name": "Wood_Softwood_Roof_Shallow",
      "rotation": 2
    },
    {
      "x": -5,
      "y": 0,
      "z": -1,
      "name": "Rock_Stone"
    },
    {
      "x": -5,
      "y": 2,
      "z": -1,
      "name": "Wood_Softwood_Stairs",
      "rotation": 8
    },
    {
      "x": -5,
      "y": 3,
      "z": -1,
      "name": "Wood_Softwood_Stairs"
    },
    {
      "x": -5,
      "y": 10,
      "z": -1,
      "name": "Wood_Fir_Trunk",
      "support": 15,
      "rotation": 4
    },
    {
      "x": -5,
      "y": 15,
      "z": -1,
      "name": "Wood_Fir_Trunk",
      "support": 15,
      "rotation": 4
    },
    {
      "x": -5,
      "y": 16,
      "z": -1,
      "name": "Wood_Softwood_Planks"
    },
    {
      "x": -5,
      "y": 17,
      "z": -1,
      "name": "Wood_Softwood_Fence_Gate",
      "rotation": 1
    },
    {
      "x": -5,
      "y": 21,
      "z": -1,
      "name": "Wood_Fir_Trunk",
      "support": 15,
      "rotation": 4
    },
    {
      "x": -5,
      "y": 24,
      "z": -1,
      "name": "Wood_Softwood_Roof_Shallow",
      "filler": 32,
      "rotation": 2
    },
    {
      "x": -5,
      "y": 0,
      "z": 0,
      "name": "Rock_Stone"
    },
    {
      "x": -5,
      "y": 1,
      "z": 0,
      "name": "Wood_Softwood_Stairs",
      "rotation": 8
    },
    {
      "x": -5,
      "y": 2,
      "z": 0,
      "name": "Wood_Softwood_Stairs"
    },
    {
      "x": -5,
      "y": 10,
      "z": 0,
      "name": "Wood_Fir_Trunk",
      "support": 15,
      "rotation": 4
    },
    {
      "x": -5,
      "y": 15,
      "z": 0,
      "name": "Wood_Fir_Trunk",
      "support": 15,
      "rotation": 4
    },
    {
      "x": -5,
      "y": 16,
      "z": 0,
      "name": "Wood_Softwood_Planks"
    },
    {
      "x": -5,
      "y": 17,
      "z": 0,
      "name": "Wood_Softwood_Fence_Gate",
      "rotation": 3
    },
    {
      "x": -5,
      "y": 21,
      "z": 0,
      "name": "Wood_Fir_Trunk",
      "support": 15,
      "rotation": 4
    },
    {
      "x": -5,
      "y": 24,
      "z": 0,
      "name": "Wood_Softwood_Roof_Shallow",
      "filler": 992
    },
    {
      "x": -5,
      "y": 0,
      "z": 1,
      "name": "Rock_Stone"
    },
    {
      "x": -5,
      "y": 1,
      "z": 1,
      "name": "Wood_Softwood_Stairs"
    },
    {
      "x": -5,
      "y": 10,
      "z": 1,
      "name": "Wood_Fir_Trunk",
      "support": 15,
      "rotation": 4
    },
    {
      "x": -5,
      "y": 15,
      "z": 1,
      "name": "Wood_Fir_Trunk",
      "support": 15,
      "rotation": 4
    },
    {
      "x": -5,
      "y": 16,
      "z": 1,
      "name": "Wood_Softwood_Planks"
    },
    {
      "x": -5,
      "y": 17,
      "z": 1,
      "name": "Wood_Softwood_Fence_Gate",
      "rotation": 1
    },
    {
      "x": -5,
      "y": 20,
      "z": 1,
      "name": "Deco_Lantern_Ceiling"
    },
    {
      "x": -5,
      "y": 21,
      "z": 1,
      "name": "Wood_Fir_Trunk",
      "support": 15,
      "rotation": 4
    },
    {
      "x": -5,
      "y": 23,
      "z": 1,
      "name": "Wood_Softwood_Stairs",
      "rotation": 8
    },
    {
      "x": -5,
      "y": 24,
      "z": 1,
      "name": "Wood_Softwood_Roof_Shallow"
    },
    {
      "x": -5,
      "y": 0,
      "z": 2,
      "name": "Rock_Stone"
    },
    {
      "x": -5,
      "y": 10,
      "z": 2,
      "name": "Wood_Fir_Trunk",
      "support": 15,
      "rotation": 4
    },
    {
      "x": -5,
      "y": 15,
      "z": 2,
      "name": "Wood_Fir_Trunk",
      "support": 15,
      "rotation": 4
    },
    {
      "x": -5,
      "y": 16,
      "z": 2,
      "name": "Wood_Softwood_Planks"
    },
    {
      "x": -5,
      "y": 17,
      "z": 2,
      "name": "Wood_Softwood_Fence_Gate",
      "rotation": 3
    },
    {
      "x": -5,
      "y": 21,
      "z": 2,
      "name": "Wood_Fir_Trunk",
      "support": 15,
      "rotation": 4
    },
    {
      "x": -5,
      "y": 23,
      "z": 2,
      "name": "Wood_Softwood_Roof_Shallow",
      "filler": 992
    },
    {
      "x": -5,
      "y": 0,
      "z": 3,
      "name": "Rock_Stone"
    },
    {
      "x": -5,
      "y": 10,
      "z": 3,
      "name": "Wood_Fir_Trunk",
      "support": 15,
      "rotation": 4
    },
    {
      "x": -5,
      "y": 15,
      "z": 3,
      "name": "Wood_Fir_Trunk",
      "support": 15,
      "rotation": 4
    },
    {
      "x": -5,
      "y": 16,
      "z": 3,
      "name": "Wood_Softwood_Planks"
    },
    {
      "x": -5,
      "y": 17,
      "z": 3,
      "name": "Wood_Softwood_Fence_Gate",
      "rotation": 1
    },
    {
      "x": -5,
      "y": 21,
      "z": 3,
      "name": "Wood_Fir_Trunk",
      "support": 15,
      "rotation": 4
    },
    {
      "x": -5,
      "y": 22,
      "z": 3,
      "name": "Wood_Softwood_Stairs",
      "rotation": 8
    },
    {
      "x": -5,
      "y": 23,
      "z": 3,
      "name": "Wood_Softwood_Roof_Shallow"
    },
    {
      "x": -5,
      "y": 0,
      "z": 4,
      "name": "Rock_Stone"
    },
    {
      "x": -5,
      "y": 1,
      "z": 4,
      "name": "Wood_Fir_Trunk",
      "support": 15
    },
    {
      "x": -5,
      "y": 2,
      "z": 4,
      "name": "Wood_Fir_Trunk",
      "support": 15
    },
    {
      "x": -5,
      "y": 3,
      "z": 4,
      "name": "Wood_Fir_Trunk",
      "support": 15
    },
    {
      "x": -5,
      "y": 4,
      "z": 4,
      "name": "Wood_Fir_Trunk",
      "support": 15
    },
    {
      "x": -5,
      "y": 5,
      "z": 4,
      "name": "Wood_Fir_Trunk",
      "support": 15
    },
    {
      "x": -5,
      "y": 6,
      "z": 4,
      "name": "Wood_Fir_Trunk",
      "support": 15,
      "rotation": 5
    },
    {
      "x": -5,
      "y": 7,
      "z": 4,
      "name": "Wood_Fir_Trunk",
      "support": 15
    },
    {
      "x": -5,
      "y": 8,
      "z": 4,
      "name": "Wood_Fir_Trunk",
      "support": 15
    },
    {
      "x": -5,
      "y": 9,
      "z": 4,
      "name": "Wood_Fir_Trunk",
      "support": 15
    },
    {
      "x": -5,
      "y": 10,
      "z": 4,
      "name": "Wood_Fir_Trunk",
      "support": 15,
      "rotation": 4
    },
    {
      "x": -5,
      "y": 11,
      "z": 4,
      "name": "Wood_Fir_Trunk",
      "support": 15
    },
    {
      "x": -5,
      "y": 12,
      "z": 4,
      "name": "Wood_Fir_Trunk",
      "support": 15
    },
    {
      "x": -5,
      "y": 13,
      "z": 4,
      "name": "Wood_Fir_Trunk",
      "support": 15
    },
    {
      "x": -5,
      "y": 14,
      "z": 4,
      "name": "Wood_Fir_Trunk",
      "support": 15
    },
    {
      "x": -5,
      "y": 15,
      "z": 4,
      "name": "Wood_Fir_Trunk",
      "support": 15
    },
    {
      "x": -5,
      "y": 16,
      "z": 4,
      "name": "Wood_Fir_Trunk",
      "support": 15
    },
    {
      "x": -5,
      "y": 17,
      "z": 4,
      "name": "Wood_Fir_Trunk",
      "support": 15
    },
    {
      "x": -5,
      "y": 18,
      "z": 4,
      "name": "Wood_Fir_Trunk",
      "support": 15
    },
    {
      "x": -5,
      "y": 19,
      "z": 4,
      "name": "Wood_Fir_Trunk",
      "support": 15
    },
    {
      "x": -5,
      "y": 20,
      "z": 4,
      "name": "Wood_Fir_Trunk",
      "support": 15
    },
    {
      "x": -5,
      "y": 21,
      "z": 4,
      "name": "Wood_Fir_Trunk",
      "support": 15
    },
    {
      "x": -5,
      "y": 22,
      "z": 4,
      "name": "*Wood_Softwood_Roof_Shallow_State_Definitions_Inverted_Corner_Left",
      "filler": 993,
      "rotation": 3
    },
    {
      "x": -5,
      "y": 0,
      "z": 5,
      "name": "Rock_Stone"
    },
    {
      "x": -5,
      "y": 1,
      "z": 5,
      "name": "Rock_Stone"
    },
    {
      "x": -5,
      "y": 2,
      "z": 5,
      "name": "Rock_Stone"
    },
    {
      "x": -5,
      "y": 3,
      "z": 5,
      "name": "Rock_Stone"
    },
    {
      "x": -5,
      "y": 4,
      "z": 5,
      "name": "Rock_Stone"
    },
    {
      "x": -5,
      "y": 5,
      "z": 5,
      "name": "Rock_Stone"
    },
    {
      "x": -5,
      "y": 6,
      "z": 5,
      "name": "Rock_Stone"
    },
    {
      "x": -5,
      "y": 7,
      "z": 5,
      "name": "Rock_Stone"
    },
    {
      "x": -5,
      "y": 8,
      "z": 5,
      "name": "Rock_Stone"
    },
    {
      "x": -5,
      "y": 9,
      "z": 5,
      "name": "Rock_Stone"
    },
    {
      "x": -5,
      "y": 10,
      "z": 5,
      "name": "Rock_Stone"
    },
    {
      "x": -5,
      "y": 11,
      "z": 5,
      "name": "Rock_Stone"
    },
    {
      "x": -5,
      "y": 12,
      "z": 5,
      "name": "Rock_Stone"
    },
    {
      "x": -5,
      "y": 13,
      "z": 5,
      "name": "Soil_Dirt"
    },
    {
      "x": -5,
      "y": 14,
      "z": 5,
      "name": "Soil_Dirt"
    },
    {
      "x": -5,
      "y": 15,
      "z": 5,
      "name": "Soil_Dirt"
    },
    {
      "x": -5,
      "y": 16,
      "z": 5,
      "name": "Wood_Softwood_Planks"
    },
    {
      "x": -5,
      "y": 22,
      "z": 5,
      "name": "*Wood_Softwood_Roof_Shallow_State_Definitions_Inverted_Corner_Left",
      "filler": 1,
      "rotation": 3
    },
    {
      "x": -5,
      "y": 0,
      "z": 6,
      "name": "Rock_Stone"
    },
    {
      "x": -5,
      "y": 1,
      "z": 6,
      "name": "Rock_Stone"
    },
    {
      "x": -5,
      "y": 2,
      "z": 6,
      "name": "Rock_Stone"
    },
    {
      "x": -5,
      "y": 3,
      "z": 6,
      "name": "Rock_Stone"
    },
    {
      "x": -5,
      "y": 4,
      "z": 6,
      "name": "Rock_Stone"
    },
    {
      "x": -5,
      "y": 5,
      "z": 6,
      "name": "Rock_Stone"
    },
    {
      "x": -5,
      "y": 6,
      "z": 6,
      "name": "Rock_Stone"
    },
    {
      "x": -5,
      "y": 7,
      "z": 6,
      "name": "Rock_Stone"
    },
    {
      "x": -5,
      "y": 8,
      "z": 6,
      "name": "Rock_Stone"
    },
    {
      "x": -5,
      "y": 9,
      "z": 6,
      "name": "Rock_Stone"
    },
    {
      "x": -5,
      "y": 10,
      "z": 6,
      "name": "Rock_Stone"
    },
    {
      "x": -5,
      "y": 11,
      "z": 6,
      "name": "Rock_Stone"
    },
    {
      "x": -5,
      "y": 12,
      "z": 6,
      "name": "Rock_Stone"
    },
    {
      "x": -5,
      "y": 13,
      "z": 6,
      "name": "Soil_Dirt"
    },
    {
      "x": -5,
      "y": 14,
      "z": 6,
      "name": "Soil_Dirt"
    },
    {
      "x": -5,
      "y": 15,
      "z": 6,
      "name": "Soil_Dirt"
    },
    {
      "x": -5,
      "y": 16,
      "z": 6,
      "name": "Wood_Softwood_Planks"
    },
    {
      "x": -5,
      "y": 22,
      "z": 6,
      "name": "Wood_Softwood_Roof_Shallow",
      "filler": 1,
      "rotation": 3
    },
    {
      "x": -5,
      "y": 0,
      "z": 7,
      "name": "Rock_Stone"
    },
    {
      "x": -5,
      "y": 1,
      "z": 7,
      "name": "Rock_Stone"
    },
    {
      "x": -5,
      "y": 2,
      "z": 7,
      "name": "Rock_Stone"
    },
    {
      "x": -5,
      "y": 3,
      "z": 7,
      "name": "Rock_Stone"
    },
    {
      "x": -5,
      "y": 4,
      "z": 7,
      "name": "Rock_Stone"
    },
    {
      "x": -5,
      "y": 5,
      "z": 7,
      "name": "Rock_Stone"
    },
    {
      "x": -5,
      "y": 6,
      "z": 7,
      "name": "Rock_Stone"
    },
    {
      "x": -5,
      "y": 7,
      "z": 7,
      "name": "Rock_Stone"
    },
    {
      "x": -5,
      "y": 8,
      "z": 7,
      "name": "Rock_Stone"
    },
    {
      "x": -5,
      "y": 9,
      "z": 7,
      "name": "Rock_Stone"
    },
    {
      "x": -5,
      "y": 10,
      "z": 7,
      "name": "Rock_Stone"
    },
    {
      "x": -5,
      "y": 11,
      "z": 7,
      "name": "Rock_Stone"
    },
    {
      "x": -5,
      "y": 12,
      "z": 7,
      "name": "Rock_Stone"
    },
    {
      "x": -5,
      "y": 13,
      "z": 7,
      "name": "Soil_Dirt"
    },
    {
      "x": -5,
      "y": 14,
      "z": 7,
      "name": "Soil_Dirt"
    },
    {
      "x": -5,
      "y": 15,
      "z": 7,
      "name": "Soil_Dirt"
    },
    {
      "x": -5,
      "y": 16,
      "z": 7,
      "name": "Wood_Softwood_Planks"
    },
    {
      "x": -5,
      "y": 22,
      "z": 7,
      "name": "Wood_Softwood_Roof_Shallow",
      "filler": 1,
      "rotation": 3
    },
    {
      "x": -5,
      "y": 0,
      "z": 8,
      "name": "Rock_Stone"
    },
    {
      "x": -5,
      "y": 1,
      "z": 8,
      "name": "Rock_Stone"
    },
    {
      "x": -5,
      "y": 2,
      "z": 8,
      "name": "Rock_Stone"
    },
    {
      "x": -5,
      "y": 3,
      "z": 8,
      "name": "Rock_Stone"
    },
    {
      "x": -5,
      "y": 4,
      "z": 8,
      "name": "Rock_Stone"
    },
    {
      "x": -5,
      "y": 5,
      "z": 8,
      "name": "Rock_Stone"
    },
    {
      "x": -5,
      "y": 6,
      "z": 8,
      "name": "Rock_Stone"
    },
    {
      "x": -5,
      "y": 7,
      "z": 8,
      "name": "Rock_Stone"
    },
    {
      "x": -5,
      "y": 8,
      "z": 8,
      "name": "Rock_Stone"
    },
    {
      "x": -5,
      "y": 9,
      "z": 8,
      "name": "Rock_Stone"
    },
    {
      "x": -5,
      "y": 10,
      "z": 8,
      "name": "Rock_Stone"
    },
    {
      "x": -5,
      "y": 11,
      "z": 8,
      "name": "Rock_Stone"
    },
    {
      "x": -5,
      "y": 12,
      "z": 8,
      "name": "Rock_Stone"
    },
    {
      "x": -5,
      "y": 13,
      "z": 8,
      "name": "Soil_Dirt"
    },
    {
      "x": -5,
      "y": 14,
      "z": 8,
      "name": "Soil_Dirt"
    },
    {
      "x": -5,
      "y": 15,
      "z": 8,
      "name": "Soil_Dirt"
    },
    {
      "x": -5,
      "y": 16,
      "z": 8,
      "name": "Soil_Grass"
    },
    {
      "x": -4,
      "y": 0,
      "z": -7,
      "name": "Rock_Stone"
    },
    {
      "x": -4,
      "y": 1,
      "z": -7,
      "name": "Rock_Stone"
    },
    {
      "x": -4,
      "y": 2,
      "z": -7,
      "name": "Rock_Stone"
    },
    {
      "x": -4,
      "y": 3,
      "z": -7,
      "name": "Rock_Stone"
    },
    {
      "x": -4,
      "y": 4,
      "z": -7,
      "name": "Rock_Stone"
    },
    {
      "x": -4,
      "y": 5,
      "z": -7,
      "name": "Rock_Stone"
    },
    {
      "x": -4,
      "y": 6,
      "z": -7,
      "name": "Rock_Stone"
    },
    {
      "x": -4,
      "y": 7,
      "z": -7,
      "name": "Rock_Stone"
    },
    {
      "x": -4,
      "y": 8,
      "z": -7,
      "name": "Rock_Stone"
    },
    {
      "x": -4,
      "y": 9,
      "z": -7,
      "name": "Rock_Stone"
    },
    {
      "x": -4,
      "y": 10,
      "z": -7,
      "name": "Rock_Stone"
    },
    {
      "x": -4,
      "y": 11,
      "z": -7,
      "name": "Rock_Stone"
    },
    {
      "x": -4,
      "y": 12,
      "z": -7,
      "name": "Rock_Stone"
    },
    {
      "x": -4,
      "y": 13,
      "z": -7,
      "name": "Soil_Dirt"
    },
    {
      "x": -4,
      "y": 14,
      "z": -7,
      "name": "Soil_Dirt"
    },
    {
      "x": -4,
      "y": 15,
      "z": -7,
      "name": "Soil_Dirt"
    },
    {
      "x": -4,
      "y": 16,
      "z": -7,
      "name": "Soil_Grass"
    },
    {
      "x": -4,
      "y": 0,
      "z": -6,
      "name": "Rock_Stone"
    },
    {
      "x": -4,
      "y": 1,
      "z": -6,
      "name": "Rock_Stone"
    },
    {
      "x": -4,
      "y": 2,
      "z": -6,
      "name": "Rock_Stone"
    },
    {
      "x": -4,
      "y": 3,
      "z": -6,
      "name": "Rock_Stone"
    },
    {
      "x": -4,
      "y": 4,
      "z": -6,
      "name": "Rock_Stone"
    },
    {
      "x": -4,
      "y": 5,
      "z": -6,
      "name": "Rock_Stone"
    },
    {
      "x": -4,
      "y": 6,
      "z": -6,
      "name": "Rock_Stone"
    },
    {
      "x": -4,
      "y": 7,
      "z": -6,
      "name": "Rock_Stone"
    },
    {
      "x": -4,
      "y": 8,
      "z": -6,
      "name": "Rock_Stone"
    },
    {
      "x": -4,
      "y": 9,
      "z": -6,
      "name": "Rock_Stone"
    },
    {
      "x": -4,
      "y": 10,
      "z": -6,
      "name": "Rock_Stone"
    },
    {
      "x": -4,
      "y": 11,
      "z": -6,
      "name": "Rock_Stone"
    },
    {
      "x": -4,
      "y": 12,
      "z": -6,
      "name": "Rock_Stone"
    },
    {
      "x": -4,
      "y": 13,
      "z": -6,
      "name": "Rock_Stone"
    },
    {
      "x": -4,
      "y": 14,
      "z": -6,
      "name": "Rock_Stone"
    },
    {
      "x": -4,
      "y": 15,
      "z": -6,
      "name": "Soil_Dirt"
    },
    {
      "x": -4,
      "y": 16,
      "z": -6,
      "name": "Wood_Softwood_Planks"
    },
    {
      "x": -4,
      "y": 23,
      "z": -6,
      "name": "Wood_Softwood_Stairs",
      "rotation": 11
    },
    {
      "x": -4,
      "y": 24,
      "z": -6,
      "name": "Wood_Softwood_Roof_Shallow",
      "rotation": 3
    },
    {
      "x": -4,
      "y": 0,
      "z": -5,
      "name": "Rock_Stone"
    },
    {
      "x": -4,
      "y": 3,
      "z": -5,
      "name": "Wood_Fir_Trunk",
      "support": 15,
      "rotation": 5
    },
    {
      "x": -4,
      "y": 4,
      "z": -5,
      "name": "Wood_Softwood_Planks"
    },
    {
      "x": -4,
      "y": 15,
      "z": -5,
      "name": "Wood_Fir_Trunk",
      "support": 15,
      "rotation": 5
    },
    {
      "x": -4,
      "y": 16,
      "z": -5,
      "name": "Wood_Softwood_Planks"
    },
    {
      "x": -4,
      "y": 17,
      "z": -5,
      "name": "*Wood_Softwood_Fence_Gate_State_Definitions_CloseDoorIn"
    },
    {
      "x": -4,
      "y": 23,
      "z": -5,
      "name": "Wood_Softwood_Stairs",
      "rotation": 11
    },
    {
      "x": -4,
      "y": 24,
      "z": -5,
      "name": "Wood_Softwood_Roof_Shallow",
      "rotation": 3
    },
    {
      "x": -4,
      "y": 0,
      "z": -4,
      "name": "Rock_Stone"
    },
    {
      "x": -4,
      "y": 4,
      "z": -4,
      "name": "Wood_Softwood_Planks"
    },
    {
      "x": -4,
      "y": 16,
      "z": -4,
      "name": "Wood_Softwood_Planks"
    },
    {
      "x": -4,
      "y": 23,
      "z": -4,
      "name": "Wood_Softwood_Stairs",
      "rotation": 11
    },
    {
      "x": -4,
      "y": 24,
      "z": -4,
      "name": "Wood_Softwood_Roof_Shallow",
      "rotation": 3
    },
    {
      "x": -4,
      "y": 0,
      "z": -3,
      "name": "Rock_Stone"
    },
    {
      "x": -4,
      "y": 4,
      "z": -3,
      "name": "Wood_Softwood_Planks"
    },
    {
      "x": -4,
      "y": 16,
      "z": -3,
      "name": "Wood_Softwood_Planks"
    },
    {
      "x": -4,
      "y": 23,
      "z": -3,
      "name": "Wood_Softwood_Stairs",
      "rotation": 11
    },
    {
      "x": -4,
      "y": 24,
      "z": -3,
      "name": "Wood_Softwood_Roof_Shallow",
      "rotation": 3
    },
    {
      "x": -4,
      "y": 0,
      "z": -2,
      "name": "Rock_Stone"
    },
    {
      "x": -4,
      "y": 3,
      "z": -2,
      "name": "Wood_Fir_Trunk",
      "support": 15,
      "rotation": 5
    },
    {
      "x": -4,
      "y": 4,
      "z": -2,
      "name": "Wood_Softwood_Stairs"
    },
    {
      "x": -4,
      "y": 16,
      "z": -2,
      "name": "Wood_Softwood_Planks"
    },
    {
      "x": -4,
      "y": 23,
      "z": -2,
      "name": "*Wood_Softwood_Stairs_State_Definitions_Corner_Left",
      "rotation": 11
    },
    {
      "x": -4,
      "y": 24,
      "z": -2,
      "name": "*Wood_Softwood_Roof_Shallow_State_Definitions_Inverted_Corner_Left",
      "rotation": 2
    },
    {
      "x": -4,
      "y": 0,
      "z": -1,
      "name": "Rock_Stone"
    },
    {
      "x": -4,
      "y": 2,
      "z": -1,
      "name": "Wood_Softwood_Stairs",
      "rotation": 8
    },
    {
      "x": -4,
      "y": 3,
      "z": -1,
      "name": "Wood_Softwood_Stairs"
    },
    {
      "x": -4,
      "y": 16,
      "z": -1,
      "name": "Wood_Softwood_Planks"
    },
    {
      "x": -4,
      "y": 24,
      "z": -1,
      "name": "*Wood_Softwood_Roof_Shallow_State_Definitions_Inverted_Corner_Left",
      "filler": 32,
      "rotation": 2
    },
    {
      "x": -4,
      "y": 0,
      "z": 0,
      "name": "Rock_Stone"
    },
    {
      "x": -4,
      "y": 1,
      "z": 0,
      "name": "Wood_Softwood_Stairs",
      "rotation": 8
    },
    {
      "x": -4,
      "y": 2,
      "z": 0,
      "name": "Wood_Softwood_Stairs"
    },
    {
      "x": -4,
      "y": 16,
      "z": 0,
      "name": "Wood_Softwood_Planks"
    },
    {
      "x": -4,
      "y": 24,
      "z": 0,
      "name": "Wood_Softwood_Roof_Shallow",
      "filler": 992
    },
    {
      "x": -4,
      "y": 0,
      "z": 1,
      "name": "Rock_Stone"
    },
    {
      "x": -4,
      "y": 1,
      "z": 1,
      "name": "Wood_Softwood_Stairs"
    },
    {
      "x": -4,
      "y": 16,
      "z": 1,
      "name": "Wood_Softwood_Planks"
    },
    {
      "x": -4,
      "y": 23,
      "z": 1,
      "name": "Wood_Softwood_Stairs",
      "rotation": 8
    },
    {
      "x": -4,
      "y": 24,
      "z": 1,
      "name": "Wood_Softwood_Roof_Shallow"
    },
    {
      "x": -4,
      "y": 0,
      "z": 2,
      "name": "Rock_Stone"
    },
    {
      "x": -4,
      "y": 16,
      "z": 2,
      "name": "Wood_Softwood_Planks"
    },
    {
      "x": -4,
      "y": 23,
      "z": 2,
      "name": "*Wood_Softwood_Roof_Shallow_State_Definitions_Inverted_Corner_Right",
      "filler": 992
    },
    {
      "x": -4,
      "y": 0,
      "z": 3,
      "name": "Rock_Stone"
    },
    {
      "x": -4,
      "y": 16,
      "z": 3,
      "name": "Wood_Softwood_Planks"
    },
    {
      "x": -4,
      "y": 22,
      "z": 3,
      "name": "*Wood_Softwood_Stairs_State_Definitions_Corner_Right",
      "rotation": 11
    },
    {
      "x": -4,
      "y": 23,
      "z": 3,
      "name": "*Wood_Softwood_Roof_Shallow_State_Definitions_Inverted_Corner_Right"
    },
    {
      "x": -4,
      "y": 0,
      "z": 4,
      "name": "Rock_Stone"
    },
    {
      "x": -4,
      "y": 6,
      "z": 4,
      "name": "Wood_Fir_Trunk",
      "support": 15,
      "rotation": 5
    },
    {
      "x": -4,
      "y": 11,
      "z": 4,
      "name": "Wood_Fir_Trunk",
      "support": 15,
      "rotation": 5
    },
    {
      "x": -4,
      "y": 15,
      "z": 4,
      "name": "Wood_Fir_Trunk",
      "support": 15,
      "rotation": 5
    },
    {
      "x": -4,
      "y": 16,
      "z": 4,
      "name": "Wood_Softwood_Planks"
    },
    {
      "x": -4,
      "y": 21,
      "z": 4,
      "name": "Wood_Fir_Trunk",
      "support": 15,
      "rotation": 5
    },
    {
      "x": -4,
      "y": 22,
      "z": 4,
      "name": "Wood_Softwood_Stairs",
      "rotation": 11
    },
    {
      "x": -4,
      "y": 23,
      "z": 4,
      "name": "Wood_Softwood_Roof_Shallow",
      "rotation": 3
    },
    {
      "x": -4,
      "y": 0,
      "z": 5,
      "name": "Rock_Stone"
    },
    {
      "x": -4,
      "y": 5,
      "z": 5,
      "name": "Rock_Stone"
    },
    {
      "x": -4,
      "y": 6,
      "z": 5,
      "name": "Rock_Stone"
    },
    {
      "x": -4,
      "y": 7,
      "z": 5,
      "name": "Rock_Stone"
    },
    {
      "x": -4,
      "y": 8,
      "z": 5,
      "name": "Rock_Stone"
    },
    {
      "x": -4,
      "y": 9,
      "z": 5,
      "name": "Rock_Stone"
    },
    {
      "x": -4,
      "y": 10,
      "z": 5,
      "name": "Rock_Stone"
    },
    {
      "x": -4,
      "y": 11,
      "z": 5,
      "name": "Rock_Stone"
    },
    {
      "x": -4,
      "y": 12,
      "z": 5,
      "name": "Rock_Stone"
    },
    {
      "x": -4,
      "y": 13,
      "z": 5,
      "name": "Rock_Stone"
    },
    {
      "x": -4,
      "y": 14,
      "z": 5,
      "name": "Rock_Stone"
    },
    {
      "x": -4,
      "y": 16,
      "z": 5,
      "name": "Wood_Softwood_Planks"
    },
    {
      "x": -4,
      "y": 22,
      "z": 5,
      "name": "Wood_Softwood_Stairs",
      "rotation": 11
    },
    {
      "x": -4,
      "y": 23,
      "z": 5,
      "name": "Wood_Softwood_Roof_Shallow",
      "rotation": 3
    },
    {
      "x": -4,
      "y": 0,
      "z": 6,
      "name": "Rock_Stone"
    },
    {
      "x": -4,
      "y": 5,
      "z": 6,
      "name": "Rock_Stone"
    },
    {
      "x": -4,
      "y": 6,
      "z": 6,
      "name": "Rock_Stone"
    },
    {
      "x": -4,
      "y": 7,
      "z": 6,
      "name": "Rock_Stone"
    },
    {
      "x": -4,
      "y": 8,
      "z": 6,
      "name": "Rock_Stone"
    },
    {
      "x": -4,
      "y": 9,
      "z": 6,
      "name": "Rock_Stone"
    },
    {
      "x": -4,
      "y": 10,
      "z": 6,
      "name": "Rock_Stone"
    },
    {
      "x": -4,
      "y": 11,
      "z": 6,
      "name": "Rock_Stone"
    },
    {
      "x": -4,
      "y": 12,
      "z": 6,
      "name": "Rock_Stone"
    },
    {
      "x": -4,
      "y": 13,
      "z": 6,
      "name": "Soil_Dirt"
    },
    {
      "x": -4,
      "y": 14,
      "z": 6,
      "name": "Soil_Dirt"
    },
    {
      "x": -4,
      "y": 15,
      "z": 6,
      "name": "Soil_Dirt"
    },
    {
      "x": -4,
      "y": 16,
      "z": 6,
      "name": "Wood_Softwood_Planks"
    },
    {
      "x": -4,
      "y": 22,
      "z": 6,
      "name": "Wood_Softwood_Stairs",
      "rotation": 11
    },
    {
      "x": -4,
      "y": 23,
      "z": 6,
      "name": "Wood_Softwood_Roof_Shallow",
      "rotation": 3
    },
    {
      "x": -4,
      "y": 0,
      "z": 7,
      "name": "Rock_Stone"
    },
    {
      "x": -4,
      "y": 1,
      "z": 7,
      "name": "Rock_Stone"
    },
    {
      "x": -4,
      "y": 2,
      "z": 7,
      "name": "Rock_Stone"
    },
    {
      "x": -4,
      "y": 3,
      "z": 7,
      "name": "Rock_Stone"
    },
    {
      "x": -4,
      "y": 4,
      "z": 7,
      "name": "Rock_Stone"
    },
    {
      "x": -4,
      "y": 5,
      "z": 7,
      "name": "Rock_Stone"
    },
    {
      "x": -4,
      "y": 6,
      "z": 7,
      "name": "Rock_Stone"
    },
    {
      "x": -4,
      "y": 7,
      "z": 7,
      "name": "Rock_Stone"
    },
    {
      "x": -4,
      "y": 8,
      "z": 7,
      "name": "Rock_Stone"
    },
    {
      "x": -4,
      "y": 9,
      "z": 7,
      "name": "Rock_Stone"
    },
    {
      "x": -4,
      "y": 10,
      "z": 7,
      "name": "Rock_Stone"
    },
    {
      "x": -4,
      "y": 11,
      "z": 7,
      "name": "Rock_Stone"
    },
    {
      "x": -4,
      "y": 12,
      "z": 7,
      "name": "Rock_Stone"
    },
    {
      "x": -4,
      "y": 13,
      "z": 7,
      "name": "Soil_Dirt"
    },
    {
      "x": -4,
      "y": 14,
      "z": 7,
      "name": "Soil_Dirt"
    },
    {
      "x": -4,
      "y": 15,
      "z": 7,
      "name": "Soil_Dirt"
    },
    {
      "x": -4,
      "y": 16,
      "z": 7,
      "name": "Wood_Softwood_Planks"
    },
    {
      "x": -4,
      "y": 22,
      "z": 7,
      "name": "Wood_Softwood_Stairs",
      "rotation": 11
    },
    {
      "x": -4,
      "y": 23,
      "z": 7,
      "name": "Wood_Softwood_Roof_Shallow",
      "rotation": 3
    },
    {
      "x": -4,
      "y": 0,
      "z": 8,
      "name": "Rock_Stone"
    },
    {
      "x": -4,
      "y": 1,
      "z": 8,
      "name": "Rock_Stone"
    },
    {
      "x": -4,
      "y": 2,
      "z": 8,
      "name": "Rock_Stone"
    },
    {
      "x": -4,
      "y": 3,
      "z": 8,
      "name": "Rock_Stone"
    },
    {
      "x": -4,
      "y": 4,
      "z": 8,
      "name": "Rock_Stone"
    },
    {
      "x": -4,
      "y": 5,
      "z": 8,
      "name": "Rock_Stone"
    },
    {
      "x": -4,
      "y": 6,
      "z": 8,
      "name": "Rock_Stone"
    },
    {
      "x": -4,
      "y": 7,
      "z": 8,
      "name": "Rock_Stone"
    },
    {
      "x": -4,
      "y": 8,
      "z": 8,
      "name": "Rock_Stone"
    },
    {
      "x": -4,
      "y": 9,
      "z": 8,
      "name": "Rock_Stone"
    },
    {
      "x": -4,
      "y": 10,
      "z": 8,
      "name": "Rock_Stone"
    },
    {
      "x": -4,
      "y": 11,
      "z": 8,
      "name": "Rock_Stone"
    },
    {
      "x": -4,
      "y": 12,
      "z": 8,
      "name": "Rock_Stone"
    },
    {
      "x": -4,
      "y": 13,
      "z": 8,
      "name": "Soil_Dirt"
    },
    {
      "x": -4,
      "y": 14,
      "z": 8,
      "name": "Soil_Dirt"
    },
    {
      "x": -4,
      "y": 15,
      "z": 8,
      "name": "Soil_Dirt"
    },
    {
      "x": -4,
      "y": 16,
      "z": 8,
      "name": "Soil_Grass"
    },
    {
      "x": -3,
      "y": 0,
      "z": -7,
      "name": "Rock_Stone"
    },
    {
      "x": -3,
      "y": 1,
      "z": -7,
      "name": "Rock_Stone"
    },
    {
      "x": -3,
      "y": 2,
      "z": -7,
      "name": "Rock_Stone"
    },
    {
      "x": -3,
      "y": 3,
      "z": -7,
      "name": "Rock_Stone"
    },
    {
      "x": -3,
      "y": 4,
      "z": -7,
      "name": "Rock_Stone"
    },
    {
      "x": -3,
      "y": 5,
      "z": -7,
      "name": "Rock_Stone"
    },
    {
      "x": -3,
      "y": 6,
      "z": -7,
      "name": "Rock_Stone"
    },
    {
      "x": -3,
      "y": 7,
      "z": -7,
      "name": "Rock_Stone"
    },
    {
      "x": -3,
      "y": 8,
      "z": -7,
      "name": "Rock_Stone"
    },
    {
      "x": -3,
      "y": 9,
      "z": -7,
      "name": "Rock_Stone"
    },
    {
      "x": -3,
      "y": 10,
      "z": -7,
      "name": "Rock_Stone"
    },
    {
      "x": -3,
      "y": 11,
      "z": -7,
      "name": "Rock_Stone"
    },
    {
      "x": -3,
      "y": 12,
      "z": -7,
      "name": "Rock_Stone"
    },
    {
      "x": -3,
      "y": 13,
      "z": -7,
      "name": "Soil_Dirt"
    },
    {
      "x": -3,
      "y": 14,
      "z": -7,
      "name": "Soil_Dirt"
    },
    {
      "x": -3,
      "y": 15,
      "z": -7,
      "name": "Soil_Dirt"
    },
    {
      "x": -3,
      "y": 16,
      "z": -7,
      "name": "Soil_Grass"
    },
    {
      "x": -3,
      "y": 0,
      "z": -6,
      "name": "Rock_Stone"
    },
    {
      "x": -3,
      "y": 1,
      "z": -6,
      "name": "Rock_Stone"
    },
    {
      "x": -3,
      "y": 2,
      "z": -6,
      "name": "Rock_Stone"
    },
    {
      "x": -3,
      "y": 3,
      "z": -6,
      "name": "Rock_Stone"
    },
    {
      "x": -3,
      "y": 4,
      "z": -6,
      "name": "Rock_Stone"
    },
    {
      "x": -3,
      "y": 5,
      "z": -6,
      "name": "Rock_Stone"
    },
    {
      "x": -3,
      "y": 6,
      "z": -6,
      "name": "Rock_Stone"
    },
    {
      "x": -3,
      "y": 7,
      "z": -6,
      "name": "Rock_Stone"
    },
    {
      "x": -3,
      "y": 8,
      "z": -6,
      "name": "Rock_Stone"
    },
    {
      "x": -3,
      "y": 9,
      "z": -6,
      "name": "Rock_Stone"
    },
    {
      "x": -3,
      "y": 10,
      "z": -6,
      "name": "Rock_Stone"
    },
    {
      "x": -3,
      "y": 11,
      "z": -6,
      "name": "Rock_Stone"
    },
    {
      "x": -3,
      "y": 12,
      "z": -6,
      "name": "Rock_Stone"
    },
    {
      "x": -3,
      "y": 13,
      "z": -6,
      "name": "Rock_Stone"
    },
    {
      "x": -3,
      "y": 14,
      "z": -6,
      "name": "Rock_Stone"
    },
    {
      "x": -3,
      "y": 15,
      "z": -6,
      "name": "Soil_Dirt"
    },
    {
      "x": -3,
      "y": 16,
      "z": -6,
      "name": "Wood_Softwood_Planks"
    },
    {
      "x": -3,
      "y": 24,
      "z": -6,
      "name": "Wood_Softwood_Roof_Shallow",
      "filler": 1,
      "rotation": 3
    },
    {
      "x": -3,
      "y": 0,
      "z": -5,
      "name": "Rock_Stone"
    },
    {
      "x": -3,
      "y": 3,
      "z": -5,
      "name": "Wood_Fir_Trunk",
      "support": 15,
      "rotation": 5
    },
    {
      "x": -3,
      "y": 4,
      "z": -5,
      "name": "Wood_Softwood_Planks"
    },
    {
      "x": -3,
      "y": 15,
      "z": -5,
      "name": "Wood_Fir_Trunk",
      "support": 15,
      "rotation": 5
    },
    {
      "x": -3,
      "y": 16,
      "z": -5,
      "name": "Wood_Softwood_Planks"
    },
    {
      "x": -3,
      "y": 17,
      "z": -5,
      "name": "*Wood_Softwood_Fence_Gate_State_Definitions_CloseDoorOut",
      "rotation": 2
    },
    {
      "x": -3,
      "y": 24,
      "z": -5,
      "name": "Wood_Softwood_Roof_Shallow",
      "filler": 1,
      "rotation": 3
    },
    {
      "x": -3,
      "y": 0,
      "z": -4,
      "name": "Rock_Stone"
    },
    {
      "x": -3,
      "y": 4,
      "z": -4,
      "name": "Wood_Softwood_Planks"
    },
    {
      "x": -3,
      "y": 16,
      "z": -4,
      "name": "Wood_Softwood_Planks"
    },
    {
      "x": -3,
      "y": 24,
      "z": -4,
      "name": "Wood_Softwood_Roof_Shallow",
      "filler": 1,
      "rotation": 3
    },
    {
      "x": -3,
      "y": 0,
      "z": -3,
      "name": "Rock_Stone"
    },
    {
      "x": -3,
      "y": 4,
      "z": -3,
      "name": "Wood_Softwood_Planks"
    },
    {
      "x": -3,
      "y": 16,
      "z": -3,
      "name": "Wood_Softwood_Planks"
    },
    {
      "x": -3,
      "y": 24,
      "z": -3,
      "name": "Wood_Softwood_Roof_Shallow",
      "filler": 1,
      "rotation": 3
    },
    {
      "x": -3,
      "y": 0,
      "z": -2,
      "name": "Rock_Stone"
    },
    {
      "x": -3,
      "y": 3,
      "z": -2,
      "name": "Wood_Fir_Trunk",
      "support": 15,
      "rotation": 5
    },
    {
      "x": -3,
      "y": 4,
      "z": -2,
      "name": "Wood_Softwood_Stairs"
    },
    {
      "x": -3,
      "y": 7,
      "z": -2,
      "name": "Wood_Torch_Wall",
      "rotation": 3
    },
    {
      "x": -3,
      "y": 16,
      "z": -2,
      "name": "Wood_Softwood_Planks"
    },
    {
      "x": -3,
      "y": 24,
      "z": -2,
      "name": "*Wood_Softwood_Roof_Shallow_State_Definitions_Inverted_Corner_Left",
      "filler": 1,
      "rotation": 2
    },
    {
      "x": -3,
      "y": 0,
      "z": -1,
      "name": "Rock_Stone"
    },
    {
      "x": -3,
      "y": 2,
      "z": -1,
      "name": "Wood_Softwood_Stairs",
      "rotation": 8
    },
    {
      "x": -3,
      "y": 3,
      "z": -1,
      "name": "Wood_Softwood_Stairs"
    },
    {
      "x": -3,
      "y": 16,
      "z": -1,
      "name": "Wood_Softwood_Planks"
    },
    {
      "x": -3,
      "y": 24,
      "z": -1,
      "name": "*Wood_Softwood_Roof_Shallow_State_Definitions_Inverted_Corner_Left",
      "filler": 33,
      "rotation": 2
    },
    {
      "x": -3,
      "y": 0,
      "z": 0,
      "name": "Rock_Stone"
    },
    {
      "x": -3,
      "y": 1,
      "z": 0,
      "name": "Wood_Softwood_Stairs",
      "rotation": 8
    },
    {
      "x": -3,
      "y": 2,
      "z": 0,
      "name": "Wood_Softwood_Stairs"
    },
    {
      "x": -3,
      "y": 16,
      "z": 0,
      "name": "Wood_Softwood_Planks"
    },
    {
      "x": -3,
      "y": 24,
      "z": 0,
      "name": "Wood_Softwood_Roof_Shallow",
      "filler": 992
    },
    {
      "x": -3,
      "y": 0,
      "z": 1,
      "name": "Rock_Stone"
    },
    {
      "x": -3,
      "y": 1,
      "z": 1,
      "name": "Wood_Softwood_Stairs"
    },
    {
      "x": -3,
      "y": 4,
      "z": 1,
      "name": "Wood_Torch_Wall",
      "rotation": 3
    },
    {
      "x": -3,
      "y": 16,
      "z": 1,
      "name": "Wood_Softwood_Planks"
    },
    {
      "x": -3,
      "y": 23,
      "z": 1,
      "name": "Wood_Softwood_Stairs",
      "rotation": 8
    },
    {
      "x": -3,
      "y": 24,
      "z": 1,
      "name": "Wood_Softwood_Roof_Shallow"
    },
    {
      "x": -3,
      "y": 0,
      "z": 2,
      "name": "Rock_Stone"
    },
    {
      "x": -3,
      "y": 16,
      "z": 2,
      "name": "Wood_Softwood_Planks"
    },
    {
      "x": -3,
      "y": 23,
      "z": 2,
      "name": "*Wood_Softwood_Roof_Shallow_State_Definitions_Inverted_Corner_Right",
      "filler": 993
    },
    {
      "x": -3,
      "y": 0,
      "z": 3,
      "name": "Rock_Stone"
    },
    {
      "x": -3,
      "y": 16,
      "z": 3,
      "name": "Wood_Softwood_Planks"
    },
    {
      "x": -3,
      "y": 23,
      "z": 3,
      "name": "*Wood_Softwood_Roof_Shallow_State_Definitions_Inverted_Corner_Right",
      "filler": 1
    },
    {
      "x": -3,
      "y": 0,
      "z": 4,
      "name": "Rock_Stone"
    },
    {
      "x": -3,
      "y": 6,
      "z": 4,
      "name": "Wood_Fir_Trunk",
      "support": 15,
      "rotation": 5
    },
    {
      "x": -3,
      "y": 11,
      "z": 4,
      "name": "Wood_Fir_Trunk",
      "support": 15,
      "rotation": 5
    },
    {
      "x": -3,
      "y": 15,
      "z": 4,
      "name": "Wood_Fir_Trunk",
      "support": 15,
      "rotation": 5
    },
    {
      "x": -3,
      "y": 16,
      "z": 4,
      "name": "Wood_Softwood_Planks"
    },
    {
      "x": -3,
      "y": 21,
      "z": 4,
      "name": "Wood_Fir_Trunk",
      "support": 15,
      "rotation": 5
    },
    {
      "x": -3,
      "y": 23,
      "z": 4,
      "name": "Wood_Softwood_Roof_Shallow",
      "filler": 1,
      "rotation": 3
    },
    {
      "x": -3,
      "y": 0,
      "z": 5,
      "name": "Rock_Stone"
    },
    {
      "x": -3,
      "y": 6,
      "z": 5,
      "name": "Rock_Stone"
    },
    {
      "x": -3,
      "y": 7,
      "z": 5,
      "name": "Rock_Stone"
    },
    {
      "x": -3,
      "y": 8,
      "z": 5,
      "name": "Rock_Stone"
    },
    {
      "x": -3,
      "y": 9,
      "z": 5,
      "name": "Rock_Stone"
    },
    {
      "x": -3,
      "y": 10,
      "z": 5,
      "name": "Rock_Stone"
    },
    {
      "x": -3,
      "y": 11,
      "z": 5,
      "name": "Rock_Stone"
    },
    {
      "x": -3,
      "y": 12,
      "z": 5,
      "name": "Rock_Stone"
    },
    {
      "x": -3,
      "y": 13,
      "z": 5,
      "name": "Rock_Stone"
    },
    {
      "x": -3,
      "y": 14,
      "z": 5,
      "name": "Rock_Stone"
    },
    {
      "x": -3,
      "y": 15,
      "z": 5,
      "name": "Soil_Dirt"
    },
    {
      "x": -3,
      "y": 16,
      "z": 5,
      "name": "Wood_Softwood_Planks"
    },
    {
      "x": -3,
      "y": 23,
      "z": 5,
      "name": "Wood_Softwood_Roof_Shallow",
      "filler": 1,
      "rotation": 3
    },
    {
      "x": -3,
      "y": 0,
      "z": 6,
      "name": "Rock_Stone"
    },
    {
      "x": -3,
      "y": 5,
      "z": 6,
      "name": "Rock_Stone"
    },
    {
      "x": -3,
      "y": 6,
      "z": 6,
      "name": "Rock_Stone"
    },
    {
      "x": -3,
      "y": 7,
      "z": 6,
      "name": "Rock_Stone"
    },
    {
      "x": -3,
      "y": 8,
      "z": 6,
      "name": "Rock_Stone"
    },
    {
      "x": -3,
      "y": 9,
      "z": 6,
      "name": "Rock_Stone"
    },
    {
      "x": -3,
      "y": 10,
      "z": 6,
      "name": "Rock_Stone"
    },
    {
      "x": -3,
      "y": 11,
      "z": 6,
      "name": "Rock_Stone"
    },
    {
      "x": -3,
      "y": 12,
      "z": 6,
      "name": "Rock_Stone"
    },
    {
      "x": -3,
      "y": 13,
      "z": 6,
      "name": "Soil_Dirt"
    },
    {
      "x": -3,
      "y": 14,
      "z": 6,
      "name": "Soil_Dirt"
    },
    {
      "x": -3,
      "y": 15,
      "z": 6,
      "name": "Soil_Dirt"
    },
    {
      "x": -3,
      "y": 16,
      "z": 6,
      "name": "Wood_Softwood_Planks"
    },
    {
      "x": -3,
      "y": 23,
      "z": 6,
      "name": "Wood_Softwood_Roof_Shallow",
      "filler": 1,
      "rotation": 3
    },
    {
      "x": -3,
      "y": 0,
      "z": 7,
      "name": "Rock_Stone"
    },
    {
      "x": -3,
      "y": 1,
      "z": 7,
      "name": "Wood_Fir_Trunk",
      "support": 15
    },
    {
      "x": -3,
      "y": 2,
      "z": 7,
      "name": "Wood_Fir_Trunk",
      "support": 15
    },
    {
      "x": -3,
      "y": 3,
      "z": 7,
      "name": "Wood_Fir_Trunk",
      "support": 15
    },
    {
      "x": -3,
      "y": 4,
      "z": 7,
      "name": "Wood_Fir_Trunk",
      "support": 15
    },
    {
      "x": -3,
      "y": 5,
      "z": 7,
      "name": "Rock_Stone"
    },
    {
      "x": -3,
      "y": 6,
      "z": 7,
      "name": "Rock_Stone"
    },
    {
      "x": -3,
      "y": 7,
      "z": 7,
      "name": "Rock_Stone"
    },
    {
      "x": -3,
      "y": 8,
      "z": 7,
      "name": "Rock_Stone"
    },
    {
      "x": -3,
      "y": 9,
      "z": 7,
      "name": "Rock_Stone"
    },
    {
      "x": -3,
      "y": 10,
      "z": 7,
      "name": "Rock_Stone"
    },
    {
      "x": -3,
      "y": 11,
      "z": 7,
      "name": "Rock_Stone"
    },
    {
      "x": -3,
      "y": 12,
      "z": 7,
      "name": "Rock_Stone"
    },
    {
      "x": -3,
      "y": 13,
      "z": 7,
      "name": "Soil_Dirt"
    },
    {
      "x": -3,
      "y": 14,
      "z": 7,
      "name": "Soil_Dirt"
    },
    {
      "x": -3,
      "y": 15,
      "z": 7,
      "name": "Soil_Dirt"
    },
    {
      "x": -3,
      "y": 16,
      "z": 7,
      "name": "Wood_Softwood_Planks"
    },
    {
      "x": -3,
      "y": 23,
      "z": 7,
      "name": "Wood_Softwood_Roof_Shallow",
      "filler": 1,
      "rotation": 3
    },
    {
      "x": -3,
      "y": 0,
      "z": 8,
      "name": "Rock_Stone"
    },
    {
      "x": -3,
      "y": 1,
      "z": 8,
      "name": "Rock_Stone"
    },
    {
      "x": -3,
      "y": 2,
      "z": 8,
      "name": "Rock_Stone"
    },
    {
      "x": -3,
      "y": 3,
      "z": 8,
      "name": "Rock_Stone"
    },
    {
      "x": -3,
      "y": 4,
      "z": 8,
      "name": "Rock_Stone"
    },
    {
      "x": -3,
      "y": 5,
      "z": 8,
      "name": "Rock_Stone"
    },
    {
      "x": -3,
      "y": 6,
      "z": 8,
      "name": "Rock_Stone"
    },
    {
      "x": -3,
      "y": 7,
      "z": 8,
      "name": "Rock_Stone"
    },
    {
      "x": -3,
      "y": 8,
      "z": 8,
      "name": "Rock_Stone"
    },
    {
      "x": -3,
      "y": 9,
      "z": 8,
      "name": "Rock_Stone"
    },
    {
      "x": -3,
      "y": 10,
      "z": 8,
      "name": "Rock_Stone"
    },
    {
      "x": -3,
      "y": 11,
      "z": 8,
      "name": "Rock_Stone"
    },
    {
      "x": -3,
      "y": 12,
      "z": 8,
      "name": "Rock_Stone"
    },
    {
      "x": -3,
      "y": 13,
      "z": 8,
      "name": "Soil_Dirt"
    },
    {
      "x": -3,
      "y": 14,
      "z": 8,
      "name": "Soil_Dirt"
    },
    {
      "x": -3,
      "y": 15,
      "z": 8,
      "name": "Soil_Dirt"
    },
    {
      "x": -3,
      "y": 16,
      "z": 8,
      "name": "Soil_Grass"
    },
    {
      "x": -2,
      "y": 0,
      "z": -7,
      "name": "Rock_Stone"
    },
    {
      "x": -2,
      "y": 1,
      "z": -7,
      "name": "Rock_Stone"
    },
    {
      "x": -2,
      "y": 2,
      "z": -7,
      "name": "Rock_Stone"
    },
    {
      "x": -2,
      "y": 3,
      "z": -7,
      "name": "Rock_Stone"
    },
    {
      "x": -2,
      "y": 4,
      "z": -7,
      "name": "Rock_Stone"
    },
    {
      "x": -2,
      "y": 5,
      "z": -7,
      "name": "Rock_Stone"
    },
    {
      "x": -2,
      "y": 6,
