{
  "version": 8,
  "blockIdVersion": 11,
  "anchorX": 0,
  "anchorY": 0,
  "anchorZ": 0,
  "blocks": [
    {
      "x": -4,
      "y": 0,
      "z": 0,
      "name": "Rock_Stone"
    },
    {
      "x": -4,
      "y": 0,
      "z": 1,
      "name": "Rock_Stone"
    },
    {
      "x": -4,
      "y": 0,
      "z": 2,
      "name": "Rock_Stone"
    },
    {
      "x": -4,
      "y": 0,
      "z": 3,
      "name": "Rock_Stone"
    },
    {
      "x": -4,
      "y": 0,
      "z": 4,
      "name": "Rock_Stone"
    },
    {
      "x": -4,
      "y": 0,
      "z": 5,
      "name": "Rock_Stone"
    },
    {
      "x": -4,
      "y": 0,
      "z": 6,
      "name": "Rock_Stone"
    },
    {
      "x": -4,
      "y": 0,
      "z": 7,
      "name": "Rock_Stone"
    },
    {
      "x": -3,
      "y": 0,
      "z": 0,
      "name": "Rock_Stone"
    },
    {
      "x": -3,
      "y": 0,
      "z": 1,
      "name": "Rock_Stone"
    },
    {
      "x": -3,
      "y": 0,
      "z": 2,
      "name": "Rock_Stone"
    },
    {
      "x": -3,
      "y": 0,
      "z": 3,
      "name": "Rock_Stone"
    },
    {
      "x": -3,
      "y": 0,
      "z": 4,
      "name": "Rock_Stone"
    },
    {
      "x": -3,
      "y": 0,
      "z": 5,
      "name": "Rock_Stone"
    },
    {
      "x": -3,
      "y": 0,
      "z": 6,
      "name": "Rock_Stone"
    },
    {
      "x": -3,
      "y": 0,
      "z": 7,
      "name": "Rock_Stone"
    },
    {
      "x": -2,
      "y": 0,
      "z": 0,
      "name": "Rock_Stone"
    },
    {
      "x": -2,
      "y": 0,
      "z": 1,
      "name": "Rock_Stone"
    },
    {
      "x": -2,
      "y": 0,
      "z": 2,
      "name": "Rock_Stone"
    },
    {
      "x": -2,
      "y": 0,
      "z": 3,
      "name": "Rock_Stone"
    },
    {
      "x": -2,
      "y": 0,
      "z": 4,
      "name": "Rock_Stone"
    },
    {
      "x": -2,
      "y": 0,
      "z": 5,
      "name": "Rock_Stone"
    },
    {
      "x": -2,
      "y": 0,
      "z": 6,
      "name": "Rock_Stone"
    },
    {
      "x": -2,
      "y": 0,
      "z": 7,
      "name": "Rock_Stone"
    },
    {
      "x": -1,
      "y": 0,
      "z": 0,
      "name": "Rock_Stone"
    },
    {
      "x": -1,
      "y": 0,
      "z": 1,
      "name": "Rock_Stone"
    },
    {
      "x": -1,
      "y": 0,
      "z": 2,
      "name": "Rock_Stone"
    },
    {
      "x": -1,
      "y": 0,
      "z": 3,
      "name": "Rock_Stone"
    },
    {
      "x": -1,
      "y": 0,
      "z": 4,
      "name": "Rock_Stone"
    },
    {
      "x": -1,
      "y": 0,
      "z": 5,
      "name": "Rock_Stone"
    },
    {
      "x": -1,
      "y": 0,
      "z": 6,
      "name": "Rock_Stone"
    },
    {
      "x": -1,
      "y": 0,
      "z": 7,
      "name": "Rock_Stone"
    },
    {
      "x": 0,
      "y": 0,
      "z": 0,
      "name": "Rock_Stone"
    },
    {
      "x": 0,
      "y": 0,
      "z": 1,
      "name": "Rock_Stone"
    },
    {
      "x": 0,
      "y": 0,
      "z": 2,
      "name": "Rock_Stone"
    },
    {
      "x": 0,
      "y": 0,
      "z": 3,
      "name": "Rock_Stone"
    },
    {
      "x": 0,
      "y": 0,
      "z": 4,
      "name": "Rock_Stone"
    },
    {
      "x": 0,
      "y": 0,
      "z": 5,
      "name": "Rock_Stone"
    },
    {
      "x": 0,
      "y": 0,
      "z": 6,
      "name": "Rock_Stone"
    },
    {
      "x": 0,
      "y": 0,
      "z": 7,
      "name": "Rock_Stone"
    },
    {
      "x": 1,
      "y": 0,
      "z": 0,
      "name": "Rock_Stone"
    },
    {
      "x": 1,
      "y": 0,
      "z": 1,
      "name": "Rock_Stone"
    },
    {
      "x": 1,
      "y": 0,
      "z": 2,
      "name": "Rock_Stone"
    },
    {
      "x": 1,
      "y": 0,
      "z": 3,
      "name": "Rock_Stone"
    },
    {
      "x": 1,
      "y": 0,
      "z": 4,
      "name": "Rock_Stone"
    },
    {
      "x": 1,
      "y": 0,
      "z": 5,
      "name": "Rock_Stone"
    },
    {
      "x": 1,
      "y": 0,
      "z": 6,
      "name": "Rock_Stone"
    },
    {
      "x": 1,
      "y": 0,
      "z": 7,
      "name": "Rock_Stone"
    },
    {
      "x": 2,
      "y": 0,
      "z": 0,
      "name": "Rock_Stone"
    },
    {
      "x": 2,
      "y": 0,
      "z": 1,
      "name": "Rock_Stone"
    },
    {
      "x": 2,
      "y": 0,
      "z": 2,
      "name": "Rock_Stone"
    },
    {
      "x": 2,
      "y": 0,
      "z": 3,
      "name": "Rock_Stone"
    },
    {
      "x": 2,
      "y": 0,
      "z": 4,
      "name": "Rock_Stone"
    },
    {
      "x": 2,
      "y": 0,
      "z": 5,
      "name": "Rock_Stone"
    },
    {
      "x": 2,
      "y": 0,
      "z": 6,
      "name": "Rock_Stone"
    },
    {
      "x": 2,
      "y": 0,
      "z": 7,
      "name": "Rock_Stone"
    },
    {
      "x": 3,
      "y": 0,
      "z": 0,
      "name": "Rock_Stone"
    },
    {
      "x": 3,
      "y": 0,
      "z": 1,
      "name": "Rock_Stone"
    },
    {
      "x": 3,
      "y": 0,
      "z": 2,
      "name": "Rock_Stone"
    },
    {
      "x": 3,
      "y": 0,
      "z": 3,
      "name": "Rock_Stone"
    },
    {
      "x": 3,
      "y": 0,
      "z": 4,
      "name": "Rock_Stone"
    },
    {
      "x": 3,
      "y": 0,
      "z": 5,
      "name": "Rock_Stone"
    },
    {
      "x": 3,
      "y": 0,
      "z": 6,
      "name": "Rock_Stone"
    },
    {
      "x": 3,
      "y": 0,
      "z": 7,
      "name": "Rock_Stone"
    },
    {
      "x": 4,
      "y": 0,
      "z": 0,
      "name": "Rock_Stone"
    },
    {
      "x": 4,
      "y": 0,
      "z": 1,
      "name": "Rock_Stone"
    },
    {
      "x": 4,
      "y": 0,
      "z": 2,
      "name": "Rock_Stone"
    },
    {
      "x": 4,
      "y": 0,
      "z": 3,
      "name": "Rock_Stone"
    },
    {
      "x": 4,
      "y": 0,
      "z": 4,
      "name": "Rock_Stone"
    },
    {
      "x": 4,
      "y": 0,
      "z": 5,
      "name": "Rock_Stone"
    },
    {
      "x": 4,
      "y": 0,
      "z": 6,
      "name": "Rock_Stone"
    },
    {
      "x": 4,
      "y": 0,
      "z": 7,
      "name": "Rock_Stone"
    },
    {
      "x": -4,
      "y": 1,
      "z": 0,
      "name": "Wood_Ash_Trunk"
    },
    {
      "x": -4,
      "y": 1,
      "z": 7,
      "name": "Wood_Ash_Trunk"
    },
    {
      "x": -3,
      "y": 1,
      "z": 0,
      "name": "Rock_Stone"
    },
    {
      "x": -3,
      "y": 1,
      "z": 7,
      "name": "Rock_Stone"
    },
    {
      "x": -2,
      "y": 1,
      "z": 0,
      "name": "Wood_Ash_Trunk"
    },
    {
      "x": -2,
      "y": 1,
      "z": 7,
      "name": "Wood_Ash_Trunk"
    },
    {
      "x": -1,
      "y": 1,
      "z": 0,
      "name": "Rock_Stone"
    },
    {
      "x": -1,
      "y": 1,
      "z": 7,
      "name": "Rock_Stone"
    },
    {
      "x": 0,
      "y": 1,
      "z": 7,
      "name": "Rock_Stone"
    },
    {
      "x": 1,
      "y": 1,
      "z": 0,
      "name": "Rock_Stone"
    },
    {
      "x": 1,
      "y": 1,
      "z": 7,
      "name": "Rock_Stone"
    },
    {
      "x": 2,
      "y": 1,
      "z": 0,
      "name": "Wood_Ash_Trunk"
    },
    {
      "x": 2,
      "y": 1,
      "z": 7,
      "name": "Wood_Ash_Trunk"
    },
    {
      "x": 3,
      "y": 1,
      "z": 0,
      "name": "Rock_Stone"
    },
    {
      "x": 3,
      "y": 1,
      "z": 7,
      "name": "Rock_Stone"
    },
    {
      "x": 4,
      "y": 1,
      "z": 0,
      "name": "Wood_Ash_Trunk"
    },
    {
      "x": 4,
      "y": 1,
      "z": 7,
      "name": "Wood_Ash_Trunk"
    },
    {
      "x": -4,
      "y": 1,
      "z": 1,
      "name": "Rock_Stone"
    },
    {
      "x": 4,
      "y": 1,
      "z": 1,
      "name": "Rock_Stone"
    },
    {
      "x": -4,
      "y": 1,
      "z": 2,
      "name": "Rock_Stone"
    },
    {
      "x": 4,
      "y": 1,
      "z": 2,
      "name": "Rock_Stone"
    },
    {
      "x": -4,
      "y": 1,
      "z": 3,
      "name": "Wood_Ash_Trunk"
    },
    {
      "x": 4,
      "y": 1,
      "z": 3,
      "name": "Wood_Ash_Trunk"
    },
    {
      "x": -4,
      "y": 1,
      "z": 4,
      "name": "Rock_Stone"
    },
    {
      "x": 4,
      "y": 1,
      "z": 4,
      "name": "Rock_Stone"
    },
    {
      "x": -4,
      "y": 1,
      "z": 5,
      "name": "Rock_Stone"
    },
    {
      "x": 4,
      "y": 1,
      "z": 5,
      "name": "Rock_Stone"
    },
    {
      "x": -4,
      "y": 1,
      "z": 6,
      "name": "Rock_Stone"
    },
    {
      "x": 4,
      "y": 1,
      "z": 6,
      "name": "Rock_Stone"
    },
    {
      "x": -4,
      "y": 2,
      "z": 0,
      "name": "Wood_Ash_Trunk"
    },
    {
      "x": -4,
      "y": 2,
      "z": 7,
      "name": "Wood_Ash_Trunk"
    },
    {
      "x": -3,
      "y": 2,
      "z": 0,
      "name": "Rock_Stone"
    },
    {
      "x": -3,
      "y": 2,
      "z": 7,
      "name": "Rock_Stone"
    },
    {
      "x": -2,
      "y": 2,
      "z": 0,
      "name": "Wood_Ash_Trunk"
    },
    {
      "x": -2,
      "y": 2,
      "z": 7,
      "name": "Wood_Ash_Trunk"
    },
    {
      "x": -1,
      "y": 2,
      "z": 0,
      "name": "Rock_Stone"
    },
    {
      "x": -1,
      "y": 2,
      "z": 7,
      "name": "Rock_Stone"
    },
    {
      "x": 0,
      "y": 2,
      "z": 7,
      "name": "Rock_Stone"
    },
    {
      "x": 1,
      "y": 2,
      "z": 0,
      "name": "Rock_Stone"
    },
    {
      "x": 1,
      "y": 2,
      "z": 7,
      "name": "Rock_Stone"
    },
    {
      "x": 2,
      "y": 2,
      "z": 0,
      "name": "Wood_Ash_Trunk"
    },
    {
      "x": 2,
      "y": 2,
      "z": 7,
      "name": "Wood_Ash_Trunk"
    },
    {
      "x": 3,
      "y": 2,
      "z": 0,
      "name": "Rock_Stone"
    },
    {
      "x": 3,
      "y": 2,
      "z": 7,
      "name": "Rock_Stone"
    },
    {
      "x": 4,
      "y": 2,
      "z": 0,
      "name": "Wood_Ash_Trunk"
    },
    {
      "x": 4,
      "y": 2,
      "z": 7,
      "name": "Wood_Ash_Trunk"
    },
    {
      "x": -4,
      "y": 2,
      "z": 1,
      "name": "Rock_Stone"
    },
    {
      "x": 4,
      "y": 2,
      "z": 1,
      "name": "Rock_Stone"
    },
    {
      "x": -4,
      "y": 2,
      "z": 2,
      "name": "Rock_Stone"
    },
    {
      "x": 4,
      "y": 2,
      "z": 2,
      "name": "Rock_Stone"
    },
    {
      "x": -4,
      "y": 2,
      "z": 3,
      "name": "Wood_Ash_Trunk"
    },
    {
      "x": 4,
      "y": 2,
      "z": 3,
      "name": "Wood_Ash_Trunk"
    },
    {
      "x": -4,
      "y": 2,
      "z": 4,
      "name": "Rock_Stone"
    },
    {
      "x": 4,
      "y": 2,
      "z": 4,
      "name": "Rock_Stone"
    },
    {
      "x": -4,
      "y": 2,
      "z": 5,
      "name": "Rock_Stone"
    },
    {
      "x": 4,
      "y": 2,
      "z": 5,
      "name": "Rock_Stone"
    },
    {
      "x": -4,
      "y": 2,
      "z": 6,
      "name": "Rock_Stone"
    },
    {
      "x": 4,
      "y": 2,
      "z": 6,
      "name": "Rock_Stone"
    },
    {
      "x": -4,
      "y": 3,
      "z": 0,
      "name": "Wood_Ash_Trunk"
    },
    {
      "x": -4,
      "y": 3,
      "z": 7,
      "name": "Wood_Ash_Trunk"
    },
    {
      "x": -3,
      "y": 3,
      "z": 0,
      "name": "Wood_Ash_Trunk"
    },
    {
      "x": -3,
      "y": 3,
      "z": 7,
      "name": "Wood_Ash_Trunk"
    },
    {
      "x": -2,
      "y": 3,
      "z": 0,
      "name": "Wood_Ash_Trunk"
    },
    {
      "x": -2,
      "y": 3,
      "z": 7,
      "name": "Wood_Ash_Trunk"
    },
    {
      "x": -1,
      "y": 3,
      "z": 0,
      "name": "Wood_Ash_Trunk"
    },
    {
      "x": -1,
      "y": 3,
      "z": 7,
      "name": "Wood_Ash_Trunk"
    },
    {
      "x": 0,
      "y": 3,
      "z": 0,
      "name": "Wood_Ash_Trunk"
    },
    {
      "x": 0,
      "y": 3,
      "z": 7,
      "name": "Wood_Ash_Trunk"
    },
    {
      "x": 1,
      "y": 3,
      "z": 0,
      "name": "Wood_Ash_Trunk"
    },
    {
      "x": 1,
      "y": 3,
      "z": 7,
      "name": "Wood_Ash_Trunk"
    },
    {
      "x": 2,
      "y": 3,
      "z": 0,
      "name": "Wood_Ash_Trunk"
    },
    {
      "x": 2,
      "y": 3,
      "z": 7,
      "name": "Wood_Ash_Trunk"
    },
    {
      "x": 3,
      "y": 3,
      "z": 0,
      "name": "Wood_Ash_Trunk"
    },
    {
      "x": 3,
      "y": 3,
      "z": 7,
      "name": "Wood_Ash_Trunk"
    },
    {
      "x": 4,
      "y": 3,
      "z": 0,
      "name": "Wood_Ash_Trunk"
    },
    {
      "x": 4,
      "y": 3,
      "z": 7,
      "name": "Wood_Ash_Trunk"
    },
    {
      "x": -4,
      "y": 3,
      "z": 1,
      "name": "Wood_Ash_Trunk"
    },
    {
      "x": 4,
      "y": 3,
      "z": 1,
      "name": "Wood_Ash_Trunk"
    },
    {
      "x": -4,
      "y": 3,
      "z": 2,
      "name": "Wood_Ash_Trunk"
    },
    {
      "x": 4,
      "y": 3,
      "z": 2,
      "name": "Wood_Ash_Trunk"
    },
    {
      "x": -4,
      "y": 3,
      "z": 3,
      "name": "Wood_Ash_Trunk"
    },
    {
      "x": 4,
      "y": 3,
      "z": 3,
      "name": "Wood_Ash_Trunk"
    },
    {
      "x": -4,
      "y": 3,
      "z": 4,
      "name": "Wood_Ash_Trunk"
    },
    {
      "x": 4,
      "y": 3,
      "z": 4,
      "name": "Wood_Ash_Trunk"
    },
    {
      "x": -4,
      "y": 3,
      "z": 5,
      "name": "Wood_Ash_Trunk"
    },
    {
      "x": 4,
      "y": 3,
      "z": 5,
      "name": "Wood_Ash_Trunk"
    },
    {
      "x": -4,
      "y": 3,
      "z": 6,
      "name": "Wood_Ash_Trunk"
    },
    {
      "x": 4,
      "y": 3,
      "z": 6,
      "name": "Wood_Ash_Trunk"
    },
    {
      "x": 0,
      "y": 1,
      "z": 2,
      "name": "Wood_Ash_Trunk"
    },
    {
      "x": 0,
      "y": 1,
      "z": 3,
      "name": "Wood_Ash_Trunk"
    },
    {
      "x": 0,
      "y": 1,
      "z": 4,
      "name": "Wood_Ash_Trunk"
    },
    {
      "x": 0,
      "y": 1,
      "z": 5,
      "name": "Wood_Ash_Trunk"
    },
    {
      "x": -5,
      "y": 4,
      "z": -1,
      "name": "Rock_Shale"
    },
    {
      "x": 5,
      "y": 4,
      "z": -1,
      "name": "Rock_Shale"
    },
    {
      "x": -4,
      "y": 5,
      "z": -1,
      "name": "Rock_Shale"
    },
    {
      "x": 4,
      "y": 5,
      "z": -1,
      "name": "Rock_Shale"
    },
    {
      "x": -3,
      "y": 6,
      "z": -1,
      "name": "Rock_Shale"
    },
    {
      "x": 3,
      "y": 6,
      "z": -1,
      "name": "Rock_Shale"
    },
    {
      "x": -2,
      "y": 7,
      "z": -1,
      "name": "Rock_Shale"
    },
    {
      "x": 2,
      "y": 7,
      "z": -1,
      "name": "Rock_Shale"
    },
    {
      "x": -1,
      "y": 8,
      "z": -1,
      "name": "Rock_Shale"
    },
    {
      "x": 0,
      "y": 8,
      "z": -1,
      "name": "Rock_Shale"
    },
    {
      "x": 1,
      "y": 8,
      "z": -1,
      "name": "Rock_Shale"
    },
    {
      "x": -5,
      "y": 4,
      "z": 0,
      "name": "Rock_Shale"
    },
    {
      "x": 5,
      "y": 4,
      "z": 0,
      "name": "Rock_Shale"
    },
    {
      "x": -4,
      "y": 5,
      "z": 0,
      "name": "Rock_Shale"
    },
    {
      "x": 4,
      "y": 5,
      "z": 0,
      "name": "Rock_Shale"
    },
    {
      "x": -3,
      "y": 6,
      "z": 0,
      "name": "Rock_Shale"
    },
    {
      "x": 3,
      "y": 6,
      "z": 0,
      "name": "Rock_Shale"
    },
    {
      "x": -2,
      "y": 7,
      "z": 0,
      "name": "Rock_Shale"
    },
    {
      "x": 2,
      "y": 7,
      "z": 0,
      "name": "Rock_Shale"
    },
    {
      "x": -1,
      "y": 8,
      "z": 0,
      "name": "Rock_Shale"
    },
    {
      "x": 0,
      "y": 8,
      "z": 0,
      "name": "Rock_Shale"
    },
    {
      "x": 1,
      "y": 8,
      "z": 0,
      "name": "Rock_Shale"
    },
    {
      "x": -5,
      "y": 4,
      "z": 1,
      "name": "Rock_Shale"
    },
    {
      "x": 5,
      "y": 4,
      "z": 1,
      "name": "Rock_Shale"
    },
    {
      "x": -4,
      "y": 5,
      "z": 1,
      "name": "Rock_Shale"
    },
    {
      "x": 4,
      "y": 5,
      "z": 1,
      "name": "Rock_Shale"
    },
    {
      "x": -3,
      "y": 6,
      "z": 1,
      "name": "Rock_Shale"
    },
    {
      "x": 3,
      "y": 6,
      "z": 1,
      "name": "Rock_Shale"
    },
    {
      "x": -2,
      "y": 7,
      "z": 1,
      "name": "Rock_Shale"
    },
    {
      "x": 2,
      "y": 7,
      "z": 1,
      "name": "Rock_Shale"
    },
    {
      "x": -1,
      "y": 8,
      "z": 1,
      "name": "Rock_Shale"
    },
    {
      "x": 0,
      "y": 8,
      "z": 1,
      "name": "Rock_Shale"
    },
    {
      "x": 1,
      "y": 8,
      "z": 1,
      "name": "Rock_Shale"
    },
    {
      "x": -5,
      "y": 4,
      "z": 2,
      "name": "Rock_Shale"
    },
    {
      "x": 5,
      "y": 4,
      "z": 2,
      "name": "Rock_Shale"
    },
    {
      "x": -4,
      "y": 5,
      "z": 2,
      "name": "Rock_Shale"
    },
    {
      "x": 4,
      "y": 5,
      "z": 2,
      "name": "Rock_Shale"
    },
    {
      "x": -3,
      "y": 6,
      "z": 2,
      "name": "Rock_Shale"
    },
    {
      "x": 3,
      "y": 6,
      "z": 2,
      "name": "Rock_Shale"
    },
    {
      "x": -2,
      "y": 7,
      "z": 2,
      "name": "Rock_Shale"
    },
    {
      "x": 2,
      "y": 7,
      "z": 2,
      "name": "Rock_Shale"
    },
    {
      "x": -1,
      "y": 8,
      "z": 2,
      "name": "Rock_Shale"
    },
    {
      "x": 0,
      "y": 8,
      "z": 2,
      "name": "Rock_Shale"
    },
    {
      "x": 1,
      "y": 8,
      "z": 2,
      "name": "Rock_Shale"
    },
    {
      "x": -5,
      "y": 4,
      "z": 3,
      "name": "Rock_Shale"
    },
    {
      "x": 5,
      "y": 4,
      "z": 3,
      "name": "Rock_Shale"
    },
    {
      "x": -4,
      "y": 5,
      "z": 3,
      "name": "Rock_Shale"
    },
    {
      "x": 4,
      "y": 5,
      "z": 3,
      "name": "Rock_Shale"
    },
    {
      "x": -3,
      "y": 6,
      "z": 3,
      "name": "Rock_Shale"
    },
    {
      "x": 3,
      "y": 6,
      "z": 3,
      "name": "Rock_Shale"
    },
    {
      "x": -2,
      "y": 7,
      "z": 3,
      "name": "Rock_Shale"
    },
    {
      "x": 2,
      "y": 7,
      "z": 3,
      "name": "Rock_Shale"
    },
    {
      "x": -1,
      "y": 8,
      "z": 3,
      "name": "Rock_Shale"
    },
    {
      "x": 0,
      "y": 8,
      "z": 3,
      "name": "Rock_Shale"
    },
    {
      "x": 1,
      "y": 8,
      "z": 3,
      "name": "Rock_Shale"
    },
    {
      "x": -5,
      "y": 4,
      "z": 4,
      "name": "Rock_Shale"
    },
    {
      "x": 5,
      "y": 4,
      "z": 4,
      "name": "Rock_Shale"
    },
    {
      "x": -4,
      "y": 5,
      "z": 4,
      "name": "Rock_Shale"
    },
    {
      "x": 4,
      "y": 5,
      "z": 4,
      "name": "Rock_Shale"
    },
    {
      "x": -3,
      "y": 6,
      "z": 4,
      "name": "Rock_Shale"
    },
    {
      "x": 3,
      "y": 6,
      "z": 4,
      "name": "Rock_Shale"
    },
    {
      "x": -2,
      "y": 7,
      "z": 4,
      "name": "Rock_Shale"
    },
    {
      "x": 2,
      "y": 7,
      "z": 4,
      "name": "Rock_Shale"
    },
    {
      "x": -1,
      "y": 8,
      "z": 4,
      "name": "Rock_Shale"
    },
    {
      "x": 0,
      "y": 8,
      "z": 4,
      "name": "Rock_Shale"
    },
    {
      "x": 1,
      "y": 8,
      "z": 4,
      "name": "Rock_Shale"
    },
    {
      "x": -5,
      "y": 4,
      "z": 5,
      "name": "Rock_Shale"
    },
    {
      "x": 5,
      "y": 4,
      "z": 5,
      "name": "Rock_Shale"
    },
    {
      "x": -4,
      "y": 5,
      "z": 5,
      "name": "Rock_Shale"
    },
    {
      "x": 4,
      "y": 5,
      "z": 5,
      "name": "Rock_Shale"
    },
    {
      "x": -3,
      "y": 6,
      "z": 5,
      "name": "Rock_Shale"
    },
    {
      "x": 3,
      "y": 6,
      "z": 5,
      "name": "Rock_Shale"
    },
    {
      "x": -2,
      "y": 7,
      "z": 5,
      "name": "Rock_Shale"
    },
    {
      "x": 2,
      "y": 7,
      "z": 5,
      "name": "Rock_Shale"
    },
    {
      "x": -1,
      "y": 8,
      "z": 5,
      "name": "Rock_Shale"
    },
    {
      "x": 0,
      "y": 8,
      "z": 5,
      "name": "Rock_Shale"
    },
    {
      "x": 1,
      "y": 8,
      "z": 5,
      "name": "Rock_Shale"
    },
    {
      "x": -5,
      "y": 4,
      "z": 6,
      "name": "Rock_Shale"
    },
    {
      "x": 5,
      "y": 4,
      "z": 6,
      "name": "Rock_Shale"
    },
    {
      "x": -4,
      "y": 5,
      "z": 6,
      "name": "Rock_Shale"
    },
    {
      "x": 4,
      "y": 5,
      "z": 6,
      "name": "Rock_Shale"
    },
    {
      "x": -3,
      "y": 6,
      "z": 6,
      "name": "Rock_Shale"
    },
    {
      "x": 3,
      "y": 6,
      "z": 6,
      "name": "Rock_Shale"
    },
    {
      "x": -2,
      "y": 7,
      "z": 6,
      "name": "Rock_Shale"
    },
    {
      "x": 2,
      "y": 7,
      "z": 6,
      "name": "Rock_Shale"
    },
    {
      "x": -1,
      "y": 8,
      "z": 6,
      "name": "Rock_Shale"
    },
    {
      "x": 0,
      "y": 8,
      "z": 6,
      "name": "Rock_Shale"
    },
    {
      "x": 1,
      "y": 8,
      "z": 6,
      "name": "Rock_Shale"
    },
    {
      "x": -5,
      "y": 4,
      "z": 7,
      "name": "Rock_Shale"
    },
    {
      "x": 5,
      "y": 4,
      "z": 7,
      "name": "Rock_Shale"
    },
    {
      "x": -4,
      "y": 5,
      "z": 7,
      "name": "Rock_Shale"
    },
    {
      "x": 4,
      "y": 5,
      "z": 7,
      "name": "Rock_Shale"
    },
    {
      "x": -3,
      "y": 6,
      "z": 7,
      "name": "Rock_Shale"
    },
    {
      "x": 3,
      "y": 6,
      "z": 7,
      "name": "Rock_Shale"
    },
    {
      "x": -2,
      "y": 7,
      "z": 7,
      "name": "Rock_Shale"
    },
    {
      "x": 2,
      "y": 7,
      "z": 7,
      "name": "Rock_Shale"
    },
    {
      "x": -1,
      "y": 8,
      "z": 7,
      "name": "Rock_Shale"
    },
    {
      "x": 0,
      "y": 8,
      "z": 7,
      "name": "Rock_Shale"
    },
    {
      "x": 1,
      "y": 8,
      "z": 7,
      "name": "Rock_Shale"
    },
    {
      "x": -5,
      "y": 4,
      "z": 8,
      "name": "Rock_Shale"
    },
    {
      "x": 5,
      "y": 4,
      "z": 8,
      "name": "Rock_Shale"
    },
    {
      "x": -4,
      "y": 5,
      "z": 8,
      "name": "Rock_Shale"
    },
    {
      "x": 4,
      "y": 5,
      "z": 8,
      "name": "Rock_Shale"
    },
    {
      "x": -3,
      "y": 6,
      "z": 8,
      "name": "Rock_Shale"
    },
    {
      "x": 3,
      "y": 6,
      "z": 8,
      "name": "Rock_Shale"
    },
    {
      "x": -2,
      "y": 7,
      "z": 8,
      "name": "Rock_Shale"
    },
    {
      "x": 2,
      "y": 7,
      "z": 8,
      "name": "Rock_Shale"
    },
    {
      "x": -1,
      "y": 8,
      "z": 8,
      "name": "Rock_Shale"
    },
    {
      "x": 0,
      "y": 8,
      "z": 8,
      "name": "Rock_Shale"
    },
    {
      "x": 1,
      "y": 8,
      "z": 8,
      "name": "Rock_Shale"
    },
    {
      "x": -2,
      "y": 1,
      "z": -1,
      "name": "Wood_Ash_Trunk"
    },
    {
      "x": 2,
      "y": 1,
      "z": -1,
      "name": "Wood_Ash_Trunk"
    },
    {
      "x": -2,
      "y": 2,
      "z": -1,
      "name": "Wood_Ash_Trunk"
    },
    {
      "x": 2,
      "y": 2,
      "z": -1,
      "name": "Wood_Ash_Trunk"
    },
    {
      "x": -2,
      "y": 3,
      "z": -1,
      "name": "Rock_Shale"
    },
    {
      "x": -2,
      "y": 3,
      "z": -2,
      "name": "Rock_Shale"
    },
    {
      "x": -1,
      "y": 3,
      "z": -1,
      "name": "Rock_Shale"
    },
    {
      "x": -1,
      "y": 3,
      "z": -2,
      "name": "Rock_Shale"
    },
    {
      "x": 0,
      "y": 3,
      "z": -1,
      "name": "Rock_Shale"
    },
    {
      "x": 0,
      "y": 3,
      "z": -2,
      "name": "Rock_Shale"
    },
    {
      "x": 1,
      "y": 3,
      "z": -1,
      "name": "Rock_Shale"
    },
    {
      "x": 1,
      "y": 3,
      "z": -2,
      "name": "Rock_Shale"
    },
    {
      "x": 2,
      "y": 3,
      "z": -1,
      "name": "Rock_Shale"
    },
    {
      "x": 2,
      "y": 3,
      "z": -2,
      "name": "Rock_Shale"
    },
    {
      "x": 6,
      "y": 0,
      "z": 0,
      "name": "Soil_Dirt"
    },
    {
      "x": 6,
      "y": 0,
      "z": 1,
      "name": "Soil_Dirt"
    },
    {
      "x": 6,
      "y": 0,
      "z": 2,
      "name": "Soil_Dirt"
    },
    {
      "x": 6,
      "y": 0,
      "z": 3,
      "name": "Soil_Grass"
    },
    {
      "x": 6,
      "y": 0,
      "z": 4,
      "name": "Soil_Dirt"
    },
    {
      "x": 6,
      "y": 0,
      "z": 5,
      "name": "Soil_Dirt"
    },
    {
      "x": 6,
      "y": 0,
      "z": 6,
      "name": "Soil_Dirt"
    },
    {
      "x": 6,
      "y": 0,
      "z": 7,
      "name": "Soil_Dirt"
    },
    {
      "x": 7,
      "y": 0,
      "z": 0,
      "name": "Soil_Dirt"
    },
    {
      "x": 7,
      "y": 0,
      "z": 1,
      "name": "Soil_Dirt"
    },
    {
      "x": 7,
      "y": 0,
      "z": 2,
      "name": "Soil_Dirt"
    },
    {
      "x": 7,
      "y": 0,
      "z": 3,
      "name": "Soil_Grass"
    },
    {
      "x": 7,
      "y": 0,
      "z": 4,
      "name": "Soil_Dirt"
    },
    {
      "x": 7,
      "y": 0,
      "z": 5,
      "name": "Soil_Dirt"
    },
    {
      "x": 7,
      "y": 0,
      "z": 6,
      "name": "Soil_Dirt"
    },
    {
      "x": 7,
      "y": 0,
      "z": 7,
      "name": "Soil_Dirt"
    },
    {
      "x": 8,
      "y": 0,
      "z": 0,
      "name": "Soil_Dirt"
    },
    {
      "x": 8,
      "y": 0,
      "z": 1,
      "name": "Soil_Dirt"
    },
    {
      "x": 8,
      "y": 0,
      "z": 2,
      "name": "Soil_Dirt"
    },
    {
      "x": 8,
      "y": 0,
      "z": 3,
      "name": "Soil_Grass"
    },
    {
      "x": 8,
      "y": 0,
      "z": 4,
      "name": "Soil_Dirt"
    },
    {
      "x": 8,
      "y": 0,
      "z": 5,
      "name": "Soil_Dirt"
    },
    {
      "x": 8,
      "y": 0,
      "z": 6,
      "name": "Soil_Dirt"
    },
    {
      "x": 8,
      "y": 0,
      "z": 7,
      "name": "Soil_Dirt"
    },
    {
      "x": 9,
      "y": 0,
      "z": 0,
      "name": "Soil_Dirt"
    },
    {
      "x": 9,
      "y": 0,
      "z": 1,
      "name": "Soil_Dirt"
    },
    {
      "x": 9,
      "y": 0,
      "z": 2,
      "name": "Soil_Dirt"
    },
    {
      "x": 9,
      "y": 0,
      "z": 3,
      "name": "Soil_Grass"
    },
    {
      "x": 9,
      "y": 0,
      "z": 4,
      "name": "Soil_Dirt"
    },
    {
      "x": 9,
      "y": 0,
      "z": 5,
      "name": "Soil_Dirt"
    },
    {
      "x": 9,
      "y": 0,
      "z": 6,
      "name": "Soil_Dirt"
    },
    {
      "x": 9,
      "y": 0,
      "z": 7,
      "name": "Soil_Dirt"
    },
    {
      "x": 10,
      "y": 0,
      "z": 0,
      "name": "Soil_Dirt"
    },
    {
      "x": 10,
      "y": 0,
      "z": 1,
      "name": "Soil_Dirt"
    },
    {
      "x": 10,
      "y": 0,
      "z": 2,
      "name": "Soil_Dirt"
    },
    {
      "x": 10,
      "y": 0,
      "z": 3,
      "name": "Soil_Grass"
    },
    {
      "x": 10,
      "y": 0,
      "z": 4,
      "name": "Soil_Dirt"
    },
    {
      "x": 10,
      "y": 0,
      "z": 5,
      "name": "Soil_Dirt"
    },
    {
      "x": 10,
      "y": 0,
      "z": 6,
      "name": "Soil_Dirt"
    },
    {
      "x": 10,
      "y": 0,
      "z": 7,
      "name": "Soil_Dirt"
    },
    {
      "x": 5,
      "y": 1,
      "z": 0,
      "name": "Wood_Ash_Trunk"
    },
    {
      "x": 5,
      "y": 2,
      "z": 0,
      "name": "Wood_Ash_Trunk"
    },
    {
      "x": 5,
      "y": 1,
      "z": 7,
      "name": "Wood_Ash_Trunk"
    },
    {
      "x": 5,
      "y": 2,
      "z": 7,
      "name": "Wood_Ash_Trunk"
    },
    {
      "x": 11,
      "y": 1,
      "z": 0,
      "name": "Wood_Ash_Trunk"
    },
    {
      "x": 11,
      "y": 2,
      "z": 0,
      "name": "Wood_Ash_Trunk"
    },
    {
      "x": 11,
      "y": 1,
      "z": 7,
      "name": "Wood_Ash_Trunk"
    },
    {
      "x": 11,
      "y": 2,
      "z": 7,
      "name": "Wood_Ash_Trunk"
    }
  ],
  "entities": [
    {
      "Components": {
        "Transform": {
          "Position": {
            "X": 0,
            "Y": 1,
            "Z": -5
          },
          "Rotation": {
            "Pitch": 0,
            "Yaw": 0,
            "Roll": 0
          }
        },
        "TriggerVolume": {
          "Shape": {
            "Type": "Box",
            "Min": {
              "X": -1,
              "Y": 0,
              "Z": -1
            },
            "Max": {
              "X": 1,
              "Y": 2,
              "Z": 1
            }
          },
          "Enabled": true,
          "TargetTypes": [
            "Npc"
          ],
          "Tags": {
            "civ.building": "farm",
            "civ.type": "workplace_access"
          },
          "KeepLoaded": false,
          "PrefabIndex": 0,
          "Name": "civ_farm_workplace"
        }
      }
    }
  ]
}
